Workbook

Sheet CPI-U-RS
C6: Series Reported at https://www.bls.gov/cpi/research-series/r-cpi-u-rs-home.htm
C7: 1947 | D7: 37.5
C8: 1948 | D8: 40.5
C9: 1949 | D9: 40
C10: 1950 | D10: 40.5
C11: 1951 | D11: 43.7
C12: 1952 | D12: 44.5
C13: 1953 | D13: 44.8
C14: 1954 | D14: 45.2
C15: 1955 | D15: 45
C16: 1956 | D16: 45.7
C17: 1957 | D17: 47.2
C18: 1958 | D18: 48.5
... C73: 2013 | D73: 342
C74: =+C73+1 -> 2014 | D74: 347.7
C75: =+C74+1 -> 2015 | D75: 348.3
C76: =+C75+1 -> 2016 | D76: 352.8
C77: 2017 | D77: 360.3
C78: 2018 | D78: 369.1
C79: 2019 | D79: 375.8
C80: 2020 | D80: 380.8
C81: 2021 | D81: 399.2
C82: 2022 | D82: 431.5

Sheet CPI-U
AA1: From: http://numbrary.com/sources/8e7dbdcd8a7a-cuur000-cpi-all-items or http://data.bls.gov/timeseries/CUUR0000SA0?include_graphs=false&output_type=column&years_option=all_years
AA2: Year & Month | AB2: CPI
A3: Year | B3: CPI-U | H3: Series Id: CUUR0000SA0,CUUS0000SA0 | AA3: 4750 | AB3: 9.8
A4: 1947 | B4: =+U10 -> 22.3 | H4: Not Seasonally Adjusted | AA4: 4781 | AB4: 9.8
A5: 1948 | B5: =+U11 -> 24.1 | H5: Area: U.S. city average | AA5: 4809 | AB5: 9.8
A6: 1949 | B6: =+U12 -> 23.8 | H6: Item: All items | AA6: 4840 | AB6: 9.8
A7: 1950 | B7: =+U13 -> 24.1 | H7: Base Period: 1982-84=100 | AA7: 4870 | AB7: 9.7
A8: 1951 | B8: =+U14 -> 26 | AA8: 4901 | AB8: 9.8
A9: 1952 | B9: =+U15 -> 26.5 | H9: Year | I9: Jan | J9: Feb | K9: Mar | L9: Apr | M9: May | N9: Jun | O9: Jul | P9: Aug | Q9: Sep | R9: Oct | S9: Nov | T9: Dec | U9: Annual | V9: HALF1 | W9: HALF2 | AA9: 4931 | AB9: 9.9
A10: 1953 | B10: =+U16 -> 26.7 | H10: 1947 | I10: 21.5 | J10: 21.5 | K10: 21.9 | L10: 21.9 | M10: 21.9 | N10: 22 | O10: 22.2 | P10: 22.5 | Q10: 23 | R10: 23 | S10: 23.1 | T10: 23.4 | U10: 22.3 | AA10: 4962 | AB10: 9.9
A11: 1954 | B11: =+U17 -> 26.9 | H11: 1948 | I11: 23.7 | J11: 23.5 | K11: 23.4 | L11: 23.8 | M11: 23.9 | N11: 24.1 | O11: 24.4 | P11: 24.5 | Q11: 24.5 | R11: 24.4 | S11: 24.2 | T11: 24.1 | U11: 24.1 | AA11: 4993 | AB11: 10
A12: 1955 | B12: =+U18 -> 26.8 | H12: 1949 | I12: 24 | J12: 23.8 | K12: 23.8 | L12: 23.9 | M12: 23.8 | N12: 23.9 | O12: 23.7 | P12: 23.8 | Q12: 23.9 | R12: 23.7 | S12: 23.8 | T12: 23.6 | U12: 23.8 | AA12: 5023 | AB12: 10
A13: 1956 | B13: =+U19 -> 27.2 | H13: 1950 | I13: 23.5 | J13: 23.5 | K13: 23.6 | L13: 23.6 | M13: 23.7 | N13: 23.8 | O13: 24.1 | P13: 24.3 | Q13: 24.4 | R13: 24.6 | S13: 24.7 | T13: 25 | U13: 24.1 | AA13: 5054 | AB13: 10.1
A14: 1957 | B14: =+U20 -> 28.1 | H14: 1951 | I14: 25.4 | J14: 25.7 | K14: 25.8 | L14: 25.8 | M14: 25.9 | N14: 25.9 | O14: 25.9 | P14: 25.9 | Q14: 26.1 | R14: 26.2 | S14: 26.4 | T14: 26.5 | U14: 26 | AA14: 5084 | AB14: 10
A15: 1958 | B15: =+U21 -> 28.9 | H15: 1952 | I15: 26.5 | J15: 26.3 | K15: 26.3 | L15: 26.4 | M15: 26.4 | N15: 26.5 | O15: 26.7 | P15: 26.7 | Q15: 26.7 | R15: 26.7 | S15: 26.7 | T15: 26.7 | U15: 26.5 | AA15: 5115 | AB15: 10
A16: 1959 | B16: =+U22 -> 29.1 | H16: 1953 | I16: 26.6 | J16: 26.5 | K16: 26.6 | L16: 26.6 | M16: 26.7 | N16: 26.8 | O16: 26.8 | P16: 26.9 | Q16: 26.9 | R16: 27 | S16: 26.9 | T16: 26.9 | U16: 26.7 | AA16: 5146 | AB16: 9.9
A17: 1960 | B17: =+U23 -> 29.6 | H17: 1954 | I17: 26.9 | J17: 26.9 | K17: 26.9 | L17: 26.8 | M17: 26.9 | N17: 26.9 | O17: 26.9 | P17: 26.9 | Q17: 26.8 | R17: 26.8 | S17: 26.8 | T17: 26.7 | U17: 26.9 | AA17: 5174 | AB17: 9.9
A18: 1961 | B18: =+U24 -> 29.9 | H18: 1955 | I18: 26.7 | J18: 26.7 | K18: 26.7 | L18: 26.7 | M18: 26.7 | N18: 26.7 | O18: 26.8 | P18: 26.8 | Q18: 26.9 | R18: 26.9 | S18: 26.9 | T18: 26.8 | U18: 26.8 | AA18: 5205 | AB18: 9.8
A19: 1962 | B19: =+U25 -> 30.2 | H19: 1956 | I19: 26.8 | J19: 26.8 | K19: 26.8 | L19: 26.9 | M19: 27 | N19: 27.2 | O19: 27.4 | P19: 27.3 | Q19: 27.4 | R19: 27.5 | S19: 27.5 | T19: 27.6 | U19: 27.2 | AA19: 5235 | AB19: 9.9
A20: 1963 | B20: =+U26 -> 30.6 | H20: 1957 | I20: 27.6 | J20: 27.7 | K20: 27.8 | L20: 27.9 | M20: 28 | N20: 28.1 | O20: 28.3 | P20: 28.3 | Q20: 28.3 | R20: 28.3 | S20: 28.4 | T20: 28.4 | U20: 28.1 | AA20: 5266 | AB20: 9.9
A21: 1964 | B21: =+U27 -> 31 | H21: 1958 | I21: 28.6 | J21: 28.6 | K21: 28.8 | L21: 28.9 | M21: 28.9 | N21: 28.9 | O21: 29 | P21: 28.9 | Q21: 28.9 | R21: 28.9 | S21: 29 | T21: 28.9 | U21: 28.9 | AA21: 5296 | AB21: 10
... A46: 1989 | B46: =+U52 -> 124 | H46: 1983 | I46: 97.8 | J46: 97.9 | K46: 97.9 | L46: 98.6 | M46: 99.2 | N46: 99.5 | O46: 99.9 | P46: 100.2 | Q46: 100.7 | R46: 101 | S46: 101.2 | T46: 101.3 | U46: 99.6 | AA46: 6058 | AB46: 10.9
A47: 1990 | B47: =+U53 -> 130.7 | H47: 1984 | I47: 101.9 | J47: 102.4 | K47: 102.6 | L47: 103.1 | M47: 103.4 | N47: 103.7 | O47: 104.1 | P47: 104.5 | Q47: 105 | R47: 105.3 | S47: 105.3 | T47: 105.3 | U47: 103.9 | V47: 102.9 | W47: 104.9 | AA47: 6089 | AB47: 11.1
A48: 1991 | B48: =+U54 -> 136.2 | H48: 1985 | I48: 105.5 | J48: 106 | K48: 106.4 | L48: 106.9 | M48: 107.3 | N48: 107.6 | O48: 107.8 | P48: 108 | Q48: 108.3 | R48: 108.7 | S48: 109 | T48: 109.3 | U48: 107.6 | V48: 106.6 | W48: 108.5 | AA48: 6119 | AB48: 11.3
A49: 1992 | B49: =+U55 -> 140.3 | H49: 1986 | I49: 109.6 | J49: 109.3 | K49: 108.8 | L49: 108.6 | M49: 108.9 | N49: 109.5 | O49: 109.5 | P49: 109.7 | Q49: 110.2 | R49: 110.3 | S49: 110.4 | T49: 110.5 | U49: 109.6 | V49: 109.1 | W49: 110.1 | AA49: 6150 | AB49: 11.5
A50: 1993 | B50: =+U56 -> 144.5 | H50: 1987 | I50: 111.2 | J50: 111.6 | K50: 112.1 | L50: 112.7 | M50: 113.1 | N50: 113.5 | O50: 113.8 | P50: 114.4 | Q50: 115 | R50: 115.3 | S50: 115.4 | T50: 115.4 | U50: 113.6 | V50: 112.4 | W50: 114.9 | AA50: 6180 | AB50: 11.6
A51: 1994 | B51: =+U57 -> 148.2 | H51: 1988 | I51: 115.7 | J51: 116 | K51: 116.5 | L51: 117.1 | M51: 117.5 | N51: 118 | O51: 118.5 | P51: 119 | Q51: 119.8 | R51: 120.2 | S51: 120.3 | T51: 120.5 | U51: 118.3 | V51: 116.8 | W51: 119.7 | AA51: 6211 | AB51: 11.7
A52: 1995 | B52: =+U58 -> 152.4 | H52: 1989 | I52: 121.1 | J52: 121.6 | K52: 122.3 | L52: 123.1 | M52: 123.8 | N52: 124.1 | O52: 124.4 | P52: 124.6 | Q52: 125 | R52: 125.6 | S52: 125.9 | T52: 126.1 | U52: 124 | V52: 122.7 | W52: 125.3 | AA52: 6242 | AB52: 12
A53: 1996 | B53: =+U59 -> 156.9 | H53: 1990 | I53: 127.4 | J53: 128 | K53: 128.7 | L53: 128.9 | M53: 129.2 | N53: 129.9 | O53: 130.4 | P53: 131.6 | Q53: 132.7 | R53: 133.5 | S53: 133.8 | T53: 133.8 | U53: 130.7 | V53: 128.7 | W53: 132.6 | AA53: 6270 | AB53: 12
A54: 1997 | B54: =+U60 -> 160.5 | H54: 1991 | I54: 134.6 | J54: 134.8 | K54: 135 | L54: 135.2 | M54: 135.6 | N54: 136 | O54: 136.2 | P54: 136.6 | Q54: 137.2 | R54: 137.4 | S54: 137.8 | T54: 137.9 | U54: 136.2 | V54: 135.2 | W54: 137.2 | AA54: 6301 | AB54: 12.6
A55: 1998 | B55: =+U61 -> 163 | H55: 1992 | I55: 138.1 | J55: 138.6 | K55: 139.3 | L55: 139.5 | M55: 139.7 | N55: 140.2 | O55: 140.5 | P55: 140.9 | Q55: 141.3 | R55: 141.8 | S55: 142 | T55: 141.9 | U55: 140.3 | V55: 139.2 | W55: 141.4 | AA55: 6331 | AB55: 12.8
A56: 1999 | B56: =+U62 -> 166.6 | H56: 1993 | I56: 142.6 | J56: 143.1 | K56: 143.6 | L56: 144 | M56: 144.2 | N56: 144.4 | O56: 144.4 | P56: 144.8 | Q56: 145.1 | R56: 145.7 | S56: 145.8 | T56: 145.8 | U56: 144.5 | V56: 143.7 | W56: 145.3 | AA56: 6362 | AB56: 13
A57: 2000 | B57: =+U63 -> 172.2 | H57: 1994 | I57: 146.2 | J57: 146.7 | K57: 147.2 | L57: 147.4 | M57: 147.5 | N57: 148 | O57: 148.4 | P57: 149 | Q57: 149.4 | R57: 149.5 | S57: 149.7 | T57: 149.7 | U57: 148.2 | V57: 147.2 | W57: 149.3 | AA57: 6392 | AB57: 12.8
A58: 2001 | B58: =+U64 -> 177.1 | H58: 1995 | I58: 150.3 | J58: 150.9 | K58: 151.4 | L58: 151.9 | M58: 152.2 | N58: 152.5 | O58: 152.5 | P58: 152.9 | Q58: 153.2 | R58: 153.7 | S58: 153.6 | T58: 153.5 | U58: 152.4 | V58: 151.5 | W58: 153.2 | AA58: 6423 | AB58: 13
... A62: 2005 | B62: =+U68 -> 195.3 | H62: 1999 | I62: 164.3 | J62: 164.5 | K62: 165 | L62: 166.2 | M62: 166.2 | N62: 166.2 | O62: 166.7 | P62: 167.1 | Q62: 167.9 | R62: 168.2 | S62: 168.3 | T62: 168.3 | U62: 166.6 | V62: 165.4 | W62: 167.8 | AA62: 6545 | AB62: 13.7
A63: =+A62+1 -> 2006 | B63: =+AVERAGE(I81:T81) -> 201.59167 | H63: 2000 | I63: 168.8 | J63: 169.8 | K63: 171.2 | L63: 171.3 | M63: 171.5 | N63: 172.4 | O63: 172.8 | P63: 172.8 | Q63: 173.7 | R63: 174 | S63: 174.1 | T63: 174 | U63: 172.2 | V63: 170.8 | W63: 173.6 | AA63: 6576 | AB63: 14
A64: =+A63+1 -> 2007 | B64: =+AVERAGE(I82:T82) -> 207.34242 | H64: 2001 | I64: 175.1 | J64: 175.8 | K64: 176.2 | L64: 176.9 | M64: 177.7 | N64: 178 | O64: 177.5 | P64: 177.5 | Q64: 178.3 | R64: 177.7 | S64: 177.4 | T64: 176.7 | U64: 177.1 | V64: 176.6 | W64: 177.5 | AA64: 6607 | AB64: 14.1
A65: =+A64+1 -> 2008 | B65: =+AVERAGE(I83:T83) -> 215.3025 | H65: 2002 | I65: 177.1 | J65: 177.8 | K65: 178.8 | L65: 179.8 | M65: 179.8 | N65: 179.9 | O65: 180.1 | P65: 180.7 | Q65: 181 | R65: 181.3 | S65: 181.3 | T65: 180.9 | U65: 179.9 | V65: 178.9 | W65: 180.9 | AA65: 6635 | AB65: 14
A66: =+A65+1 -> 2009 | B66: =+AVERAGE(I84:T84) -> 214.537 | H66: 2003 | I66: 181.7 | J66: 183.1 | K66: 184.2 | L66: 183.8 | M66: 183.5 | N66: 183.7 | O66: 183.9 | P66: 184.6 | Q66: 185.2 | R66: 185 | S66: 184.5 | T66: 184.3 | U66: 184 | V66: 183.3 | W66: 184.6 | AA66: 6666 | AB66: 14.2
A67: =+A66+1 -> 2010 | B67: =+AVERAGE(I85:T85) -> 218.0555 | H67: 2004 | I67: 185.2 | J67: 186.2 | K67: 187.4 | L67: 188 | M67: 189.1 | N67: 189.7 | O67: 189.4 | P67: 189.5 | Q67: 189.9 | R67: 190.9 | S67: 191 | T67: 190.3 | U67: 188.9 | V67: 187.6 | W67: 190.2 | AA67: 6696 | AB67: 14.5
...

Sheet PCE
D1: http://alfred.stlouisfed.org/series/downloaddata?seid=PCECTPI&cid=21 | K1: observation_date | L1: PCECTPI_20210930
B2: Year | C2: Index | D2: Base=2012 | K2: 17168 | L2: 12.226 | N2: Series ID: PCECTPI
B3: 1947 | C3: 15.702 | D3: =AVERAGE(L2:L5) -> 12.49225 | K3: 17258 | L3: 12.324 | N3: Link: http://alfred.stlouisfed.org/series?seid=PCECTPI
B4: 1948 | C4: 16.59875 | D4: =AVERAGE(L6:L9) -> 13.1995 | K4: 17349 | L4: 12.553 | N4: Help: http://alfred.stlouisfed.org/help
B5: 1949 | C5: 16.4745 | D5: =AVERAGE(L10:L13) -> 13.09575 | K5: 17441 | L5: 12.866
B6: 1950 | C6: 16.67525 | D6: =AVERAGE(L14:L17) -> 13.25175 | K6: 17533 | L6: 13.009 | N6: ALFRED (ArchivaL Federal Reserve Economic Data)
B7: 1951 | C7: 17.805 | D7: =AVERAGE(L18:L21) -> 14.1545 | K7: 17624 | L7: 13.143 | N7: Economic Research Division
B8: 1952 | C8: 18.169 | D8: =AVERAGE(L22:L25) -> 14.44475 | K8: 17715 | L8: 13.344 | N8: Federal Reserve Bank of St. Louis
B9: 1953 | C9: 18.4155 | D9: =AVERAGE(L26:L29) -> 14.6345 | K9: 17807 | L9: 13.302
B10: 1954 | C10: 18.58475 | D10: =AVERAGE(L30:L33) -> 14.758 | K10: 17899 | L10: 13.197 | N10: Output Format: Observations by Vintage Date, All Observations
B11: 1955 | C11: 18.6765 | D11: =AVERAGE(L34:L37) -> 14.8155 | K11: 17989 | L11: 13.116 | N11: File Created: 2014-10-16 1:31 PM CDT
B12: 1956 | C12: 19.0585 | D12: =AVERAGE(L38:L41) -> 15.11075 | K12: 18080 | L12: 13.04
B13: 1957 | C13: 19.63925 | D13: =AVERAGE(L42:L45) -> 15.56975 | K13: 18172 | L13: 13.03 | O13: Real-Time | P13: Period | S13: observation_date | T13: PCECTPI_20150925
B14: 1958 | C14: 20.11725 | D14: =AVERAGE(L46:L49) -> 15.93825 | K14: 18264 | L14: 13.009 | N14: Title: | O14: Start | P14: End | S14: 17168 | T14: 13.04
B15: 1959 | C15: 20.4315 | D15: =AVERAGE(L50:L53) -> 16.17575 | K15: 18354 | L15: 13.071 | N15: Personal Consumption Expenditures: Chain-type Price Index | O15: 35083 | P15: Current | S15: 17258 | T15: 13.145
B16: 1960 | C16: 20.76675 | D16: =AVERAGE(L54:L57) -> 16.44125 | K16: 18445 | L16: 13.345 | S16: 17349 | T16: 13.39
B17: 1961 | C17: 20.98475 | D17: =AVERAGE(L58:L61) -> 16.6115 | K17: 18537 | L17: 13.582 | N17: Source: | S17: 17441 | T17: 13.723
B18: 1962 | C18: 21.23175 | D18: =AVERAGE(L62:L65) -> 16.80625 | K18: 18629 | L18: 14.014 | N18: U.S. Department of Commerce: Bureau of Economic Analysis | O18: 35083 | P18: Current | S18: 17533 | T18: 13.875
B19: 1963 | C19: 21.479 | D19: =AVERAGE(L66:L69) -> 17.00725 | K19: 18719 | L19: 14.126 | S19: 17624 | T19: 14.018
B20: 1964 | C20: 21.78625 | D20: =AVERAGE(L70:L73) -> 17.2535 | K20: 18810 | L20: 14.145 | N20: Release: | S20: 17715 | T20: 14.233
B21: 1965 | C21: 22.10325 | D21: =AVERAGE(L74:L77) -> 17.502 | K21: 18902 | L21: 14.333 | N21: Gross Domestic Product | O21: 35083 | P21: Current | S21: 17807 | T21: 14.188
B22: 1966 | C22: 22.66225 | D22: =AVERAGE(L78:L81) -> 17.9445 | K22: 18994 | L22: 14.394 | S22: 17899 | T22: 14.076
B23: 1967 | C23: 23.237 | D23: =AVERAGE(L82:L85) -> 18.39525 | K23: 19085 | L23: 14.391 | N23: Units: | S23: 17989 | T23: 13.99
B24: 1968 | C24: 24.1515 | D24: =AVERAGE(L86:L89) -> 19.11525 | K24: 19176 | L24: 14.485 | N24: Index 2009=100 | O24: 41486 | P24: Current | S24: 18080 | T24: 13.91
B25: 1969 | C25: 25.255 | D25: =AVERAGE(L90:L93) -> 19.976 | K25: 19268 | L25: 14.509 | S25: 18172 | T25: 13.899
B26: 1970 | C26: 26.4485 | D26: =AVERAGE(L94:L97) -> 20.91 | K26: 19360 | L26: 14.563 | N26: Frequency: | S26: 18264 | T26: 13.876
B27: 1971 | C27: 27.5735 | D27: =AVERAGE(L98:L101) -> 21.798 | K27: 19450 | L27: 14.585 | N27: Quarterly | O27: 35083 | P27: Current | S27: 18354 | T27: 13.943
B28: 1972 | C28: 28.52775 | D28: =AVERAGE(L102:L105) -> 22.54175 | K28: 19541 | L28: 14.663 | S28: 18445 | T28: 14.235
B29: 1973 | C29: 30.08075 | D29: =AVERAGE(L106:L109) -> 23.7555 | K29: 19633 | L29: 14.727 | N29: Seasonal Adjustment: | S29: 18537 | T29: 14.488
B30: 1974 | C30: 33.191 | D30: =AVERAGE(L110:L113) -> 26.22875 | K30: 19725 | L30: 14.801 | N30: Seasonally Adjusted | O30: 35083 | P30: Current | S30: 18629 | T30: 14.949
B31: 1975 | C31: 35.95475 | D31: =AVERAGE(L114:L117) -> 28.415 | K31: 19815 | L31: 14.781 | S31: 18719 | T31: 15.068
B32: 1976 | C32: 37.94825 | D32: =AVERAGE(L118:L121) -> 29.97375 | K32: 19906 | L32: 14.732 | N32: Notes: | S32: 18810 | T32: 15.088
B33: 1977 | C33: 40.40975 | D33: =AVERAGE(L122:L125) -> 31.92325 | K33: 19998 | L33: 14.718 | N33: BEA Account Code: DPCERG3 | O33: 35083 | P33: Current | S33: 18902 | T33: 15.288
B34: 1978 | C34: 43.2485 | D34: =AVERAGE(L126:L129) -> 34.1445 | K34: 20090 | L34: 14.765 | S34: 18994 | T34: 15.353
B35: 1979 | C35: 47.059 | D35: =AVERAGE(L130:L133) -> 37.17825 | K35: 20180 | L35: 14.78 | N35: A Guide to the National Income and Product Accounts of the United | S35: 19085 | T35: 15.35
B36: 1980 | C36: 52.0775 | D36: =AVERAGE(L134:L137) -> 41.1815 | K36: 20271 | L36: 14.838 | N36: States (NIPA) - (http://www.bea.gov/national/pdf/nipaguid.pdf) | S36: 19176 | T36: 15.451
B37: 1981 | C37: 56.71975 | D37: =AVERAGE(L138:L141) -> 44.871 | K37: 20363 | L37: 14.879 | S37: 19268 | T37: 15.477
B38: 1982 | C38: 59.8585 | D38: =AVERAGE(L142:L145) -> 47.3635 | K38: 20455 | L38: 14.94 | S38: 19360 | T38: 15.536
B39: 1983 | C39: 62.436 | D39: =AVERAGE(L146:L149) -> 49.37825 | K39: 20546 | L39: 15.04 | N39: Vintage Dates Specified: | S39: 19450 | T39: 15.56
B40: 1984 | C40: 64.79525 | D40: =AVERAGE(L150:L153) -> 51.243 | K40: 20637 | L40: 15.187 | S40: 19541 | T40: 15.644
...

Sheet Sheet3
A1: Year | B1: pce | C1: cpi-u-rs | D1: cpiu | E1: cpiu-rs67 | F1: cpiu67 | G1: ratio | H1: cpiu-rs78 | I1: cpiu78 | J1: ratio | K1: pce2 | L1: cpi-u-rs2 | M1: cpiu2 | N1: cpiux | O1: pce84 | P1: cpi-u-rs84 | Q1: cpiu84
A2: 1947 | B2: =PCE!D3 -> 12.49225 | C2: =+'CPI-U-RS'!D7 -> 37.5 | D2: 22.3 | E2: =+C$22/C2 -> 1.496 | F2: =+D$22/D2 -> 1.4977578 | G2: =+E2/F2 -> 0.99882635 | H2: =+C$33/C2 -> 2.784 | I2: =+D$33/D2 -> 2.9237668 | J2: =+H2/I2 -> 0.95219632 | K2: =+B2/B$39 -> 0.24378452 | L2: =+C2/C$39 -> 0.2340824 | M2: =+D2/D$39 -> 0.21462945 | N2: 0 | O2: =+B$39/B2 -> 4.1019832 | P2: =+C$39/C2 -> 4.272 | Q2: =+D$39/D2 -> 4.6591928 | R2: 0 | S2: =+ROUND(J2,4) -> 0.9522
A3: 1948 | B3: =PCE!D4 -> 13.1995 | C3: =+'CPI-U-RS'!D8 -> 40.5 | D3: 24.1 | E3: =+C$22/C3 -> 1.3851852 | F3: =+D$22/D3 -> 1.3858921 | G3: =+E3/F3 -> 0.99948991 | H3: =+C$33/C3 -> 2.5777778 | I3: =+D$33/D3 -> 2.7053942 | J3: =+H3/I3 -> 0.9528289 | K3: =+B3/$B$39 -> 0.2575864 | L3: =+C3/C$39 -> 0.25280899 | M3: =+D3/D$39 -> 0.2319538 | N3: 0 | O3: =+B$39/B3 -> 3.8821925 | P3: =+C$39/C3 -> 3.9555556 | Q3: =+D$39/D3 -> 4.3112033 | R3: 0 | S3: =+ROUND(J3,4) -> 0.9528
A4: 1949 | B4: =PCE!D5 -> 13.09575 | C4: =+'CPI-U-RS'!D9 -> 40 | D4: 23.8 | E4: =+C$22/C4 -> 1.4025 | F4: =+D$22/D4 -> 1.4033613 | G4: =+E4/F4 -> 0.99938623 | H4: =+C$33/C4 -> 2.61 | I4: =+D$33/D4 -> 2.7394958 | J4: =+H4/I4 -> 0.95273006 | K4: =+B4/$B$39 -> 0.25556174 | L4: =+C4/C$39 -> 0.24968789 | M4: =+D4/D$39 -> 0.22906641 | N4: 0 | O4: =+B$39/B4 -> 3.9129489 | P4: =+C$39/C4 -> 4.005 | Q4: =+D$39/D4 -> 4.3655462 | R4: 0 | S4: =+ROUND(J4,4) -> 0.9527
A5: 1950 | B5: =PCE!D6 -> 13.25175 | C5: =+'CPI-U-RS'!D10 -> 40.5 | D5: 24.1 | E5: =+C$22/C5 -> 1.3851852 | F5: =+D$22/D5 -> 1.3858921 | G5: =+E5/F5 -> 0.99948991 | H5: =+C$33/C5 -> 2.5777778 | I5: =+D$33/D5 -> 2.7053942 | J5: =+H5/I5 -> 0.9528289 | K5: =+B5/$B$39 -> 0.25860605 | L5: =+C5/C$39 -> 0.25280899 | M5: =+D5/D$39 -> 0.2319538 | N5: 0.2518797 | O5: =+B$39/B5 -> 3.8668855 | P5: =+C$39/C5 -> 3.9555556 | Q5: =+D$39/D5 -> 4.3112033 | R5: 0 | S5: =+ROUND(J5,4) -> 0.9528
A6: 1951 | B6: =PCE!D7 -> 14.1545 | C6: =+'CPI-U-RS'!D11 -> 43.7 | D6: 26 | E6: =+C$22/C6 -> 1.2837529 | F6: =+D$22/D6 -> 1.2846154 | G6: =+E6/F6 -> 0.99932857 | H6: =+C$33/C6 -> 2.389016 | I6: =+D$33/D6 -> 2.5076923 | J6: =+H6/I6 -> 0.9526751 | K6: =+B6/$B$39 -> 0.27622309 | L6: =+C6/C$39 -> 0.27278402 | M6: =+D6/D$39 -> 0.25024062 | N6: 0.27255639 | O6: =+B$39/B6 -> 3.6202621 | P6: =+C$39/C6 -> 3.6659039 | Q6: =+D$39/D6 -> 3.9961538 | R6: 0 | S6: =+ROUND(J6,4) -> 0.9527
A7: 1952 | B7: =PCE!D8 -> 14.44475 | C7: =+'CPI-U-RS'!D12 -> 44.5 | D7: 26.5 | E7: =+C$22/C7 -> 1.2606742 | F7: =+D$22/D7 -> 1.2603774 | G7: =+E7/F7 -> 1.0002355 | H7: =+C$33/C7 -> 2.3460674 | I7: =+D$33/D7 -> 2.4603774 | J7: =+H7/I7 -> 0.95353967 | K7: =+B7/$B$39 -> 0.28188728 | L7: =+C7/C$39 -> 0.27777778 | M7: =+D7/D$39 -> 0.25505294 | N7: 0.27631579 | O7: =+B$39/B7 -> 3.5475173 | P7: =+C$39/C7 -> 3.6 | Q7: =+D$39/D7 -> 3.9207547 | R7: 0 | S7: =+ROUND(J7,4) -> 0.9535
A8: 1953 | B8: =PCE!D9 -> 14.6345 | C8: =+'CPI-U-RS'!D13 -> 44.8 | D8: 26.7 | E8: =+C$22/C8 -> 1.2522321 | F8: =+D$22/D8 -> 1.2509363 | G8: =+E8/F8 -> 1.0010359 | H8: =+C$33/C8 -> 2.3303571 | I8: =+D$33/D8 -> 2.4419476 | J8: =+H8/I8 -> 0.9543027 | K8: =+B8/$B$39 -> 0.28559023 | L8: =+C8/C$39 -> 0.27965044 | M8: =+D8/D$39 -> 0.25697786 | N8: 0.27819549 | O8: =+B$39/B8 -> 3.5015204 | P8: =+C$39/C8 -> 3.5758929 | Q8: =+D$39/D8 -> 3.8913858 | R8: 0 | S8: =+ROUND(J8,4) -> 0.9543
A9: 1954 | B9: =PCE!D10 -> 14.758 | C9: =+'CPI-U-RS'!D14 -> 45.2 | D9: 26.9 | E9: =+C$22/C9 -> 1.2411504 | F9: =+D$22/D9 -> 1.2416357 | G9: =+E9/F9 -> 0.99960919 | H9: =+C$33/C9 -> 2.3097345 | I9: =+D$33/D9 -> 2.4237918 | J9: =+H9/I9 -> 0.95294261 | K9: =+B9/$B$39 -> 0.28800031 | L9: =+C9/C$39 -> 0.28214732 | M9: =+D9/D$39 -> 0.25890279 | N9: 0.28195489 | O9: =+B$39/B9 -> 3.4722185 | P9: =+C$39/C9 -> 3.5442478 | Q9: =+D$39/D9 -> 3.8624535 | R9: 0 | S9: =+ROUND(J9,4) -> 0.9529
A10: 1955 | B10: =PCE!D11 -> 14.8155 | C10: =+'CPI-U-RS'!D15 -> 45 | D10: 26.8 | E10: =+C$22/C10 -> 1.2466667 | F10: =+D$22/D10 -> 1.2462687 | G10: =+E10/F10 -> 1.0003194 | H10: =+C$33/C10 -> 2.32 | I10: =+D$33/D10 -> 2.4328358 | J10: =+H10/I10 -> 0.95361963 | K10: =+B10/$B$39 -> 0.28912242 | L10: =+C10/C$39 -> 0.28089888 | M10: =+D10/D$39 -> 0.25794033 | N10: 0.28007519 | O10: =+B$39/B10 -> 3.4587425 | P10: =+C$39/C10 -> 3.56 | Q10: =+D$39/D10 -> 3.8768657 | R10: 0 | S10: =+ROUND(J10,4) -> 0.9536
A11: 1956 | B11: =PCE!D12 -> 15.11075 | C11: =+'CPI-U-RS'!D16 -> 45.7 | D11: 27.2 | E11: =+C$22/C11 -> 1.2275711 | F11: =+D$22/D11 -> 1.2279412 | G11: =+E11/F11 -> 0.99969863 | H11: =+C$33/C11 -> 2.2844639 | I11: =+D$33/D11 -> 2.3970588 | J11: =+H11/I11 -> 0.95302788 | K11: =+B11/$B$39 -> 0.29488418 | L11: =+C11/C$39 -> 0.28526841 | M11: =+D11/D$39 -> 0.26179018 | N11: 0.28571429 | O11: =+B$39/B11 -> 3.3911619 | P11: =+C$39/C11 -> 3.5054705 | Q11: =+D$39/D11 -> 3.8198529 | R11: 0 | S11: =+ROUND(J11,4) -> 0.953
A12: 1957 | B12: =PCE!D13 -> 15.56975 | C12: =+'CPI-U-RS'!D17 -> 47.2 | D12: 28.1 | E12: =+C$22/C12 -> 1.1885593 | F12: =+D$22/D12 -> 1.1886121 | G12: =+E12/F12 -> 0.9999556 | H12: =+C$33/C12 -> 2.2118644 | I12: =+D$33/D12 -> 2.3202847 | J12: =+H12/I12 -> 0.95327285 | K12: =+B12/$B$39 -> 0.3038415 | L12: =+C12/C$39 -> 0.29463171 | M12: =+D12/D$39 -> 0.27045236 | N12: 0.29323308 | O12: =+B$39/B12 -> 3.2911896 | P12: =+C$39/C12 -> 3.3940678 | Q12: =+D$39/D12 -> 3.6975089 | R12: 0 | S12: =+ROUND(J12,4) -> 0.9533
A13: 1958 | B13: =PCE!D14 -> 15.93825 | C13: =+'CPI-U-RS'!D18 -> 48.5 | D13: 28.9 | E13: =+C$22/C13 -> 1.156701 | F13: =+D$22/D13 -> 1.1557093 | G13: =+E13/F13 -> 1.0008581 | H13: =+C$33/C13 -> 2.1525773 | I13: =+D$33/D13 -> 2.2560554 | J13: =+H13/I13 -> 0.9541332 | K13: =+B13/$B$39 -> 0.31103273 | L13: =+C13/C$39 -> 0.30274657 | M13: =+D13/D$39 -> 0.27815207 | N13: 0.30263158 | O13: =+B$39/B13 -> 3.2150958 | P13: =+C$39/C13 -> 3.3030928 | Q13: =+D$39/D13 -> 3.5951557 | R13: 0 | S13: =+ROUND(J13,4) -> 0.9541
A14: 1959 | B14: =PCE!D15 -> 16.17575 | C14: =+'CPI-U-RS'!D19 -> 48.9 | D14: 29.1 | E14: =+C$22/C14 -> 1.1472393 | F14: =+D$22/D14 -> 1.1477663 | G14: =+E14/F14 -> 0.9995408 | H14: =+C$33/C14 -> 2.1349693 | I14: =+D$33/D14 -> 2.2405498 | J14: =+H14/I14 -> 0.95287741 | K14: =+B14/$B$39 -> 0.31566751 | L14: =+C14/C$39 -> 0.30524345 | M14: =+D14/D$39 -> 0.280077 | N14: 0.30451128 | O14: =+B$39/B14 -> 3.1678902 | P14: =+C$39/C14 -> 3.2760736 | Q14: =+D$39/D14 -> 3.5704467 | R14: 0 | S14: =+ROUND(J14,4) -> 0.9529
... A19: 1964 | B19: =PCE!D20 -> 17.2535 | C19: =+'CPI-U-RS'!D24 -> 52.1 | D19: 31 | E19: =+C$22/C19 -> 1.0767754 | F19: =+D$22/D19 -> 1.0774194 | G19: =+E19/F19 -> 0.99940235 | H19: =+C$33/C19 -> 2.0038388 | I19: =+D$33/D19 -> 2.1032258 | J19: =+H19/I19 -> 0.95274543 | K19: =+B19/$B$39 -> 0.33669965 | L19: =+C19/C$39 -> 0.32521848 | M19: =+D19/D$39 -> 0.29836381 | N19: 0.32518797 | O19: =+B$39/B19 -> 2.9700061 | P19: =+C$39/C19 -> 3.074856 | Q19: =+D$39/D19 -> 3.3516129 | R19: 0 | S19: =+ROUND(J19,4) -> 0.9527
A20: 1965 | B20: =PCE!D21 -> 17.502 | C20: =+'CPI-U-RS'!D25 -> 52.9 | D20: 31.5 | E20: =+C$22/C20 -> 1.0604915 | F20: =+D$22/D20 -> 1.0603175 | G20: =+E20/F20 -> 1.0001641 | H20: =+C$33/C20 -> 1.973535 | I20: =+D$33/D20 -> 2.0698413 | J20: =+H20/I20 -> 0.95347165 | K20: =+B20/$B$39 -> 0.34154909 | L20: =+C20/C$39 -> 0.33021223 | M20: =+D20/D$39 -> 0.30317613 | N20: 0.32894737 | O20: =+B$39/B20 -> 2.9278368 | P20: =+C$39/C20 -> 3.0283554 | Q20: =+D$39/D20 -> 3.2984127 | R20: 0 | S20: =+ROUND(J20,4) -> 0.9535 | U20: =+C35/C39 -> 0.79338327
A21: 1966 | B21: =PCE!D22 -> 17.9445 | C21: =+'CPI-U-RS'!D26 -> 54.4 | D21: 32.4 | E21: =+C$22/C21 -> 1.03125 | F21: =+D$22/D21 -> 1.0308642 | G21: =+E21/F21 -> 1.0003743 | H21: =+C$33/C21 -> 1.9191176 | I21: =+D$33/D21 -> 2.0123457 | J21: =+H21/I21 -> 0.95367196 | K21: =+B21/$B$39 -> 0.35018442 | L21: =+C21/C$39 -> 0.33957553 | M21: =+D21/D$39 -> 0.31183831 | N21: 0.33834586 | O21: =+B$39/B21 -> 2.8556382 | P21: =+C$39/C21 -> 2.9448529 | Q21: =+D$39/D21 -> 3.2067901 | R21: 0 | S21: =+ROUND(J21,4) -> 0.9537 | U21: =+L35/L39 -> 0.79338327
A22: 1967 | B22: =PCE!D23 -> 18.39525 | C22: =+'CPI-U-RS'!D27 -> 56.1 | D22: 33.4 | E22: =+C$22/C22 -> 1 | F22: =+D$22/D22 -> 1 | G22: =+E22/F22 -> 1 | H22: =+C$33/C22 -> 1.8609626 | I22: =+D$33/D22 -> 1.9520958 | J22: =+H22/I22 -> 0.95331518 | K22: =+B22/$B$39 -> 0.35898074 | L22: =+C22/C$39 -> 0.35018727 | M22: =+D22/D$39 -> 0.32146295 | N22: 0.34962406 | O22: =+B$39/B22 -> 2.7856648 | P22: =+C$39/C22 -> 2.855615 | Q22: =+D$39/D22 -> 3.1107784 | R22: 0 | S22: =+ROUND(J22,4) -> 0.9533
A23: 1968 | B23: =PCE!D24 -> 19.11525 | C23: =+'CPI-U-RS'!D28 -> 58.3 | D23: 34.8 | E23: =+C$22/C23 -> 0.96226415 | F23: =+D$22/D23 -> 0.95977011 | G23: =+E23/F23 -> 1.0025986 | H23: =+C$33/C23 -> 1.7907376 | I23: =+D$33/D23 -> 1.8735632 | J23: =+H23/I23 -> 0.95579244 | K23: =+B23/$B$39 -> 0.37303144 | L23: =+C23/C$39 -> 0.3639201 | M23: =+D23/D$39 -> 0.33493744 | N23: 0.36278195 | O23: =+B$39/B23 -> 2.6807392 | P23: =+C$39/C23 -> 2.7478559 | Q23: =+D$39/D23 -> 2.9856322 | R23: 0 | S23: =+ROUND(J23,4) -> 0.9558
A24: 1969 | B24: =PCE!D25 -> 19.976 | C24: =+'CPI-U-RS'!D29 -> 60.9 | D24: 36.7 | E24: =+C$22/C24 -> 0.92118227 | F24: =+D$22/D24 -> 0.91008174 | G24: =+E24/F24 -> 1.0121973 | H24: =+C$33/C24 -> 1.7142857 | I24: =+D$33/D24 -> 1.7765668 | J24: =+H24/I24 -> 0.96494303 | K24: =+B24/$B$39 -> 0.38982885 | L24: =+C24/C$39 -> 0.38014981 | M24: =+D24/D$39 -> 0.35322425 | N24: 0.37969925 | O24: =+B$39/B24 -> 2.5652283 | P24: =+C$39/C24 -> 2.6305419 | Q24: =+D$39/D24 -> 2.8310627 | R24: 0 | S24: =+ROUND(J24,4) -> 0.9649
A25: 1970 | B25: =PCE!D26 -> 20.91 | C25: =+'CPI-U-RS'!D30 -> 63.9 | D25: 38.8 | E25: =+C$22/C25 -> 0.87793427 | F25: =+D$22/D25 -> 0.86082474 | G25: =+E25/F25 -> 1.0198757 | H25: =+C$33/C25 -> 1.6338028 | I25: =+D$33/D25 -> 1.6804124 | J25: =+H25/I25 -> 0.97226303 | K25: =+B25/$B$39 -> 0.40805573 | L25: =+C25/C$39 -> 0.3988764 | M25: =+D25/D$39 -> 0.373436 | N25: 0.39661654 | O25: =+B$39/B25 -> 2.4506456 | P25: =+C$39/C25 -> 2.5070423 | Q25: =+D$39/D25 -> 2.6778351 | R25: 0 | S25: =+ROUND(J25,4) -> 0.9723
A26: 1971 | B26: =PCE!D27 -> 21.798 | C26: =+'CPI-U-RS'!D31 -> 66.7 | D26: 40.5 | E26: =+C$22/C26 -> 0.84107946 | F26: =+D$22/D26 -> 0.82469136 | G26: =+E26/F26 -> 1.0198718 | H26: =+C$33/C26 -> 1.5652174 | I26: =+D$33/D26 -> 1.6098765 | J26: =+H26/I26 -> 0.97225927 | K26: =+B26/$B$39 -> 0.42538493 | L26: =+C26/C$39 -> 0.41635456 | M26: =+D26/D$39 -> 0.38979788 | N26: 0.41541353 | O26: =+B$39/B26 -> 2.350812 | P26: =+C$39/C26 -> 2.4017991 | Q26: =+D$39/D26 -> 2.5654321 | R26: 0 | S26: =+ROUND(J26,4) -> 0.9723
A27: 1972 | B27: =PCE!D28 -> 22.54175 | C27: =+'CPI-U-RS'!D32 -> 68.7 | D27: 41.8 | E27: =+C$22/C27 -> 0.81659389 | F27: =+D$22/D27 -> 0.79904306 | G27: =+E27/F27 -> 1.0219648 | H27: =+C$33/C27 -> 1.5196507 | I27: =+D$33/D27 -> 1.5598086 | J27: =+H27/I27 -> 0.97425456 | K27: =+B27/$B$39 -> 0.43989911 | L27: =+C27/C$39 -> 0.42883895 | M27: =+D27/D$39 -> 0.40230991 | N27: 0.42669173 | O27: =+B$39/B27 -> 2.2732485 | P27: =+C$39/C27 -> 2.3318777 | Q27: =+D$39/D27 -> 2.4856459 | R27: 0 | S27: =+ROUND(J27,4) -> 0.9743
A28: 1973 | B28: =PCE!D29 -> 23.7555 | C28: =+'CPI-U-RS'!D33 -> 73 | D28: 44.4 | E28: =+C$22/C28 -> 0.76849315 | F28: =+D$22/D28 -> 0.75225225 | G28: =+E28/F28 -> 1.0215897 | H28: =+C$33/C28 -> 1.430137 | I28: =+D$33/D28 -> 1.4684685 | J28: =+H28/I28 -> 0.97389697 | K28: =+B28/$B$39 -> 0.46358527 | L28: =+C28/C$39 -> 0.4556804 | M28: =+D28/D$39 -> 0.42733397 | N28: 0.45488722 | O28: =+B$39/B28 -> 2.1571005 | P28: =+C$39/C28 -> 2.1945205 | Q28: =+D$39/D28 -> 2.3400901 | R28: 0 | S28: =+ROUND(J28,4) -> 0.9739 | X28: =60.6/62.1 -> 0.97584541
A29: 1974 | B29: =PCE!D30 -> 26.22875 | C29: =+'CPI-U-RS'!D34 -> 80.3 | D29: 49.3 | E29: =+C$22/C29 -> 0.69863014 | F29: =+D$22/D29 -> 0.67748479 | G29: =+E29/F29 -> 1.0312115 | H29: =+C$33/C29 -> 1.3001245 | I29: =+D$33/D29 -> 1.3225152 | J29: =+H29/I29 -> 0.98306962 | K29: =+B29/$B$39 -> 0.5118504 | L29: =+C29/C$39 -> 0.50124844 | M29: =+D29/D$39 -> 0.47449471 | N29: 0.5 | O29: =+B$39/B29 -> 1.9536958 | P29: =+C$39/C29 -> 1.9950187 | Q29: =+D$39/D29 -> 2.1075051 | R29: 0 | S29: =+ROUND(J29,4) -> 0.9831
A30: 1975 | B30: =PCE!D31 -> 28.415 | C30: =+'CPI-U-RS'!D35 -> 86.9 | D30: 53.8 | E30: =+C$22/C30 -> 0.64556962 | F30: =+D$22/D30 -> 0.62081784 | G30: =+E30/F30 -> 1.0398696 | H30: =+C$33/C30 -> 1.2013809 | I30: =+D$33/D30 -> 1.2118959 | J30: =+H30/I30 -> 0.9913235 | K30: =+B30/$B$39 -> 0.55451476 | L30: =+C30/C$39 -> 0.54244694 | M30: =+D30/D$39 -> 0.51780558 | N30: 0.54135338 | O30: =+B$39/B30 -> 1.8033785 | P30: =+C$39/C30 -> 1.8434983 | Q30: =+D$39/D30 -> 1.9312268 | R30: 0 | S30: =+ROUND(J30,4) -> 0.9913
A31: 1976 | B31: =PCE!D32 -> 29.97375 | C31: =+'CPI-U-RS'!D36 -> 91.9 | D31: 56.9 | E31: =+C$22/C31 -> 0.61044614 | F31: =+D$22/D31 -> 0.58699473 | G31: =+E31/F31 -> 1.0399517 | H31: =+C$33/C31 -> 1.1360174 | I31: =+D$33/D31 -> 1.1458699 | J31: =+H31/I31 -> 0.9914017 | K31: =+B31/$B$39 -> 0.58493355 | L31: =+C31/C$39 -> 0.57365793 | M31: =+D31/D$39 -> 0.54764196 | N31: 0.57142857 | O31: =+B$39/B31 -> 1.7095959 | P31: =+C$39/C31 -> 1.7431991 | Q31: =+D$39/D31 -> 1.8260105 | R31: 0 | S31: =+ROUND(J31,4) -> 0.9914 | V31: =+D32/D31 -> 1.0650264 | W31: =97.7/91.9 -> 1.0631121
A32: 1977 | B32: =PCE!D33 -> 31.92325 | C32: =+'CPI-U-RS'!D37 -> 97.7 | D32: 60.6 | E32: =+C$22/C32 -> 0.57420676 | F32: =+D$22/D32 -> 0.55115512 | G32: =+E32/F32 -> 1.0418242 | H32: =+C$33/C32 -> 1.0685773 | I32: =+D$33/D32 -> 1.0759076 | J32: =+H32/I32 -> 0.99318686 | K32: =+B32/$B$39 -> 0.62297777 | L32: =+C32/C$39 -> 0.60986267 | M32: =+D32/D$39 -> 0.58325313 | N32: 0.60902256 | O32: =+B$39/B32 -> 1.6051937 | P32: =+C$39/C32 -> 1.6397134 | Q32: =+D$39/D32 -> 1.7145215 | R32: 0 | S32: =+ROUND(J32,4) -> 0.9932 | U32: =(C32-C$33)/C$33 -> -0.064176245 | V32: =+D33/D32 -> 1.0759076 | W32: =+V32-U32 -> 1.1400838 | X32: =+D32/$D$32*97.7 -> 97.7
A33: 1978 | B33: =PCE!D34 -> 34.1445 | C33: =+'CPI-U-RS'!D38 -> 104.4 | D33: 65.2 | E33: =+C$22/C33 -> 0.53735632 | F33: =+D$22/D33 -> 0.51226994 | G33: =+E33/F33 -> 1.048971 | H33: =+C$33/C33 -> 1 | I33: =+D$33/D33 -> 1 | J33: =+H33/I33 -> 1 | K33: =+B33/$B$39 -> 0.66632516 | L33: =+C33/C$39 -> 0.65168539 | M33: =+D33/D$39 -> 0.62752647 | N33: 0.65037594 | O33: =+B$39/B33 -> 1.5007688 | P33: =+C$39/C33 -> 1.5344828 | Q33: =+D$39/D33 -> 1.5935583 | R33: 0 | S33: =+ROUND(J33,4) -> 1 | U33: =(C33-C$33)/C$33 -> 0 | V33: =(D33-D$33)/D$33 -> 0 | W33: =+V33-U33 -> 0 | X33: =+D33/$D$32*97.7 -> 105.11617 | Y33: =+X33/X32 -> 1.0759076
A34: 1979 | B34: =PCE!D35 -> 37.17825 | C34: =+'CPI-U-RS'!D39 -> 114.3 | D34: 72.6 | E34: =+C$22/C34 -> 0.49081365 | F34: =+D$22/D34 -> 0.4600551 | G34: =+E34/F34 -> 1.0668584 | H34: =+C$33/C34 -> 0.91338583 | I34: =+D$33/D34 -> 0.89807163 | J34: =+H34/I34 -> 1.0170523 | K34: =+B34/$B$39 -> 0.72552836 | L34: =+C34/C$39 -> 0.71348315 | M34: =+D34/D$39 -> 0.6987488 | N34: 0.71240602 | O34: =+B$39/B34 -> 1.3783059 | P34: =+C$39/C34 -> 1.4015748 | Q34: =+D$39/D34 -> 1.4311295 | R34: 0 | S34: =+ROUND(J34,4) -> 1.0171 | U34: =(C34-C$33)/C$33 -> 0.094827586 | V34: =(D34-D$33)/D$33 -> 0.11349693 | W34: =+V34-U34 -> 0.018669346
A35: 1980 | B35: =PCE!D36 -> 41.1815 | C35: =+'CPI-U-RS'!D40 -> 127.1 | D35: 82.4 | E35: =+C$22/C35 -> 0.44138474 | F35: =+D$22/D35 -> 0.40533981 | G35: =+E35/F35 -> 1.0889252 | H35: =+C$33/C35 -> 0.82140047 | I35: =+D$33/D35 -> 0.79126214 | J35: =+H35/I35 -> 1.0380889 | K35: =+B35/$B$39 -> 0.80365123 | L35: =+C35/C$39 -> 0.79338327 | M35: =+D35/D$39 -> 0.79307026 | N35: 0.79135338 | O35: =+B$39/B35 -> 1.2443209 | P35: =+C$39/C35 -> 1.2604249 | Q35: =+D$39/D35 -> 1.2609223 | R35: 0 | S35: =+ROUND(J35,4) -> 1.0381 | U35: =(C35-C$33)/C$33 -> 0.21743295 | V35: =(D35-D$33)/D$33 -> 0.26380368 | W35: =+V35-U35 -> 0.046370731
A36: 1981 | B36: =PCE!D37 -> 44.871 | C36: =+'CPI-U-RS'!D41 -> 139.1 | D36: 90.9 | E36: =+C$22/C36 -> 0.40330697 | F36: =+D$22/D36 -> 0.36743674 | G36: =+E36/F36 -> 1.0976229 | H36: =+C$33/C36 -> 0.75053918 | I36: =+D$33/D36 -> 0.71727173 | J36: =+H36/I36 -> 1.0463805 | K36: =+B36/$B$39 -> 0.87565131 | L36: =+C36/C$39 -> 0.86828964 | M36: =+D36/D$39 -> 0.87487969 | N36: 0.86654135 | O36: =+B$39/B36 -> 1.1420071 | P36: =+C$39/C36 -> 1.1516894 | Q36: =+D$39/D36 -> 1.1430143 | R36: 0 | S36: =+ROUND(J36,4) -> 1.0464 | U36: =(C36-C$33)/C$33 -> 0.33237548 | V36: =(D36-D$33)/D$33 -> 0.39417178 | W36: =+V36-U36 -> 0.0617963
A37: 1982 | B37: =PCE!D38 -> 47.3635 | C37: =+'CPI-U-RS'!D42 -> 147.5 | D37: 96.5 | E37: =+C$22/C37 -> 0.38033898 | F37: =+D$22/D37 -> 0.34611399 | G37: =+E37/F37 -> 1.0988836 | H37: =+C$33/C37 -> 0.70779661 | I37: =+D$33/D37 -> 0.67564767 | J37: =+H37/I37 -> 1.0475824 | K37: =+B37/$B$39 -> 0.9242921 | L37: =+C37/C$39 -> 0.92072409 | M37: =+D37/D$39 -> 0.92877767 | N37: 0.92105263 | O37: =+B$39/B37 -> 1.0819091 | P37: =+C$39/C37 -> 1.0861017 | Q37: =+D$39/D37 -> 1.0766839 | R37: 0 | S37: =+ROUND(J37,4) -> 1.0476 | U37: =(C37-C$33)/C$33 -> 0.41283525 | V37: =(D37-D$33)/D$33 -> 0.48006135 | W37: =+V37-U37 -> 0.067226101
A38: 1983 | B38: =PCE!D39 -> 49.37825 | C38: =+'CPI-U-RS'!D43 -> 153.8 | D38: 99.6 | E38: =+C$22/C38 -> 0.36475943 | F38: =+D$22/D38 -> 0.33534137 | G38: =+E38/F38 -> 1.0877257 | H38: =+C$33/C38 -> 0.67880364 | I38: =+D$33/D38 -> 0.65461847 | J38: =+H38/I38 -> 1.0369454 | K38: =+B38/$B$39 -> 0.96360966 | L38: =+C38/C$39 -> 0.96004994 | M38: =+D38/D$39 -> 0.95861405 | N38: 0.95864662 | O38: =+B$39/B38 -> 1.0377646 | P38: =+C$39/C38 -> 1.0416125 | Q38: =+D$39/D38 -> 1.0431727 | R38: 0 | S38: =+ROUND(J38,4) -> 1.0369 | U38: =(C38-C$33)/C$33 -> 0.47318008 | V38: =(D38-D$33)/D$33 -> 0.52760736 | W38: =+V38-U38 -> 0.054427285
A39: 1984 | B39: =PCE!D40 -> 51.243 | C39: =+'CPI-U-RS'!D44 -> 160.2 | D39: 103.9 | E39: =+C$22/C39 -> 0.35018727 | F39: =+D$22/D39 -> 0.32146295 | G39: =+E39/F39 -> 1.089355 | H39: =+C$33/C39 -> 0.65168539 | I39: =+D$33/D39 -> 0.62752647 | J39: =+H39/I39 -> 1.0384987 | K39: =+B39/$B$39 -> 1 | L39: =+C39/C$39 -> 1 | M39: =+D39/D$39 -> 1 | N39: 1 | O39: =+B$39/B39 -> 1 | P39: =+C$39/C39 -> 1 | Q39: =+D$39/D39 -> 1 | R39: 0 | S39: =+ROUND(J39,4) -> 1.0385 | U39: =(C39-C$33)/C$33 -> 0.53448276 | V39: =(D39-D$33)/D$33 -> 0.59355828 | W39: =+V39-U39 -> 0.059075524
A40: 1985 | B40: =PCE!D41 -> 53.03075 | C40: =+'CPI-U-RS'!D45 -> 165.6 | D40: 107.6 | E40: =+C$22/C40 -> 0.33876812 | F40: =+D$22/D40 -> 0.31040892 | G40: =+E40/F40 -> 1.0913608 | H40: =+C$33/C40 -> 0.63043478 | I40: =+D$33/D40 -> 0.60594796 | J40: =+H40/I40 -> 1.0404108 | K40: =+B40/$B$39 -> 1.0348877 | L40: =+C40/C$39 -> 1.0337079 | M40: =+D40/D$39 -> 1.0356112 | N40: 1.0357143 | O40: =+B$39/B40 -> 0.96628843 | P40: =+C$39/C40 -> 0.9673913 | Q40: =+D$39/D40 -> 0.96561338 | R40: 0 | S40: =+ROUND(J40,4) -> 1.0404 | U40: =(C40-C$33)/C$33 -> 0.5862069 | V40: =(D40-D$33)/D$33 -> 0.65030675 | W40: =+V40-U40 -> 0.064099852
A41: 1986 | B41: =PCE!D42 -> 54.18425 | C41: =+'CPI-U-RS'!D46 -> 168.4 | D41: 109.6 | E41: =+C$22/C41 -> 0.33313539 | F41: =+D$22/D41 -> 0.30474453 | G41: =+E41/F41 -> 1.0931628 | H41: =+C$33/C41 -> 0.61995249 | I41: =+D$33/D41 -> 0.59489051 | J41: =+H41/I41 -> 1.0421287 | K41: =+B41/$B$39 -> 1.0573981 | L41: =+C41/C$39 -> 1.051186 | M41: =+D41/D$39 -> 1.0548604 | N41: 1.0545113 | O41: =+B$39/B41 -> 0.94571762 | P41: =+C$39/C41 -> 0.95130641 | Q41: =+D$39/D41 -> 0.9479927 | R41: 0 | S41: =+ROUND(J41,4) -> 1.0421 | U41: =(C41-C$33)/C$33 -> 0.61302682 | V41: =(D41-D$33)/D$33 -> 0.6809816 | W41: =+V41-U41 -> 0.067954775
A42: 1987 | B42: =PCE!D43 -> 55.855 | C42: =+'CPI-U-RS'!D47 -> 174.1 | D42: 113.6 | E42: =+C$22/C42 -> 0.3222286 | F42: =+D$22/D42 -> 0.29401408 | G42: =+E42/F42 -> 1.0959632 | H42: =+C$33/C42 -> 0.59965537 | I42: =+D$33/D42 -> 0.57394366 | J42: =+H42/I42 -> 1.0447983 | K42: =+B42/$B$39 -> 1.0900025 | L42: =+C42/C$39 -> 1.0867665 | M42: =+D42/D$39 -> 1.093359 | N42: 1.093985 | O42: =+B$39/B42 -> 0.91742906 | P42: =+C$39/C42 -> 0.92016083 | Q42: =+D$39/D42 -> 0.91461268 | R42: 0 | S42: =+ROUND(J42,4) -> 1.0448 | U42: =(C42-C$33)/C$33 -> 0.66762452 | V42: =(D42-D$33)/D$33 -> 0.74233129 | W42: =+V42-U42 -> 0.074706767
A43: 1988 | B43: =PCE!D44 -> 58.0375 | C43: =+'CPI-U-RS'!D48 -> 180.5 | D43: 118.3 | E43: =+C$22/C43 -> 0.31080332 | F43: =+D$22/D43 -> 0.28233305 | G43: =+E43/F43 -> 1.1008393 | H43: =+C$33/C43 -> 0.57839335 | I43: =+D$33/D43 -> 0.55114117 | J43: =+H43/I43 -> 1.0494468 | K43: =+B43/$B$39 -> 1.1325937 | L43: =+C43/C$39 -> 1.1267166 | M43: =+D43/D$39 -> 1.1385948 | N43: 1.1390977 | O43: =+B$39/B43 -> 0.88292914 | P43: =+C$39/C43 -> 0.88753463 | Q43: =+D$39/D43 -> 0.87827557 | R43: 0 | S43: =+ROUND(J43,4) -> 1.0494 | U43: =(C43-C$33)/C$33 -> 0.7289272 | V43: =(D43-D$33)/D$33 -> 0.81441718 | W43: =+V43-U43 -> 0.085489975
A44: 1989 | B44: =PCE!D45 -> 60.572 | C44: =+'CPI-U-RS'!D49 -> 188.3 | D44: 124 | E44: =+C$22/C44 -> 0.29792884 | F44: =+D$22/D44 -> 0.26935484 | G44: =+E44/F44 -> 1.1060831 | H44: =+C$33/C44 -> 0.55443441 | I44: =+D$33/D44 -> 0.52580645 | J44: =+H44/I44 -> 1.0544458 | K44: =+B44/$B$39 -> 1.1820541 | L44: =+C44/C$39 -> 1.1754057 | M44: =+D44/D$39 -> 1.1934552 | N44: 1.193609 | O44: =+B$39/B44 -> 0.84598494 | P44: =+C$39/C44 -> 0.85077005 | Q44: =+D$39/D44 -> 0.83790323 | R44: 0 | S44: =+ROUND(J44,4) -> 1.0544 | U44: =(C44-C$33)/C$33 -> 0.80363985 | V44: =(D44-D$33)/D$33 -> 0.90184049 | W44: =+V44-U44 -> 0.098200644
...

Sheet cpi-u-rs-adj
C3: cpi-u-rs | D3: cpi-u-rs-adj .8% | E3: base=1980 | G3: check
B4: 1947 | C4: ='CPI-U-RS'!D7 -> 37.5 | D4: =+C4 -> 37.5 | E4: =+ROUND(D4/$D$37,3) -> 0.416 | K4: =+ROUND(C4/$C$62,3) -> 0.131 | L4: =+ROUND(D4/$D$62,3) -> 0.224
B5: 1948 | C5: ='CPI-U-RS'!D8 -> 40.5 | D5: =+D4+D4*((C5-C4)/C4-0.011) -> 40.0875 | E5: =+ROUND(D5/$D$37,3) -> 0.445 | G5: =+(C5-C4)/C4 -> 0.08 | H5: =+(D5-D4)/D4 -> 0.069 | I5: =+H5-G5 -> -0.011 | K5: =+ROUND(C5/$C$62,3) -> 0.141 | L5: =+ROUND(D5/$D$62,3) -> 0.24
B6: 1949 | C6: ='CPI-U-RS'!D9 -> 40 | D6: =+D5+D5*((C6-C5)/C5-0.011) -> 39.15163 | E6: =+ROUND(D6/$D$37,3) -> 0.434 | G6: =+(C6-C5)/C5 -> -0.012345679 | H6: =+(D6-D5)/D5 -> -0.023345679 | I6: =+H6-G6 -> -0.011 | K6: =+ROUND(C6/$C$62,3) -> 0.14 | L6: =+ROUND(D6/$D$62,3) -> 0.234
B7: 1950 | C7: ='CPI-U-RS'!D10 -> 40.5 | D7: =+D6+D6*((C7-C6)/C6-0.011) -> 39.210358 | E7: =+ROUND(D7/$D$37,3) -> 0.435 | G7: =+(C7-C6)/C6 -> 0.0125 | H7: =+(D7-D6)/D6 -> 0.0015 | I7: =+H7-G7 -> -0.011 | K7: =+ROUND(C7/$C$62,3) -> 0.141 | L7: =+ROUND(D7/$D$62,3) -> 0.234
B8: 1951 | C8: ='CPI-U-RS'!D11 -> 43.7 | D8: =+D7+D7*((C8-C7)/C7-0.011) -> 41.877146 | E8: =+ROUND(D8/$D$37,3) -> 0.465 | G8: =+(C8-C7)/C7 -> 0.079012346 | H8: =+(D8-D7)/D7 -> 0.068012346 | I8: =+H8-G8 -> -0.011 | K8: =+ROUND(C8/$C$62,3) -> 0.153 | L8: =+ROUND(D8/$D$62,3) -> 0.25
B9: 1952 | C9: ='CPI-U-RS'!D12 -> 44.5 | D9: =+D8+D8*((C9-C8)/C8-0.011) -> 42.183127 | E9: =+ROUND(D9/$D$37,3) -> 0.468 | G9: =+(C9-C8)/C8 -> 0.018306636 | H9: =+(D9-D8)/D8 -> 0.0073066362 | I9: =+H9-G9 -> -0.011 | K9: =+ROUND(C9/$C$62,3) -> 0.155 | L9: =+ROUND(D9/$D$62,3) -> 0.252
B10: 1953 | C10: ='CPI-U-RS'!D13 -> 44.8 | D10: =+D9+D9*((C10-C9)/C9-0.011) -> 42.003493 | E10: =+ROUND(D10/$D$37,3) -> 0.466 | G10: =+(C10-C9)/C9 -> 0.006741573 | H10: =+(D10-D9)/D9 -> -0.004258427 | I10: =+H10-G10 -> -0.011 | K10: =+ROUND(C10/$C$62,3) -> 0.156 | L10: =+ROUND(D10/$D$62,3) -> 0.251
B11: 1954 | C11: ='CPI-U-RS'!D14 -> 45.2 | D11: =+D10+D10*((C11-C10)/C10-0.011) -> 41.916486 | E11: =+ROUND(D11/$D$37,3) -> 0.465 | G11: =+(C11-C10)/C10 -> 0.0089285714 | H11: =+(D11-D10)/D10 -> -0.0020714286 | I11: =+H11-G11 -> -0.011 | K11: =+ROUND(C11/$C$62,3) -> 0.158 | L11: =+ROUND(D11/$D$62,3) -> 0.251
B12: 1955 | C12: ='CPI-U-RS'!D15 -> 45 | D12: =+D11+D11*((C12-C11)/C11-0.011) -> 41.269933 | E12: =+ROUND(D12/$D$37,3) -> 0.458 | G12: =+(C12-C11)/C11 -> -0.0044247788 | H12: =+(D12-D11)/D11 -> -0.015424779 | I12: =+H12-G12 -> -0.011 | K12: =+ROUND(C12/$C$62,3) -> 0.157 | L12: =+ROUND(D12/$D$62,3) -> 0.247
B13: 1956 | C13: ='CPI-U-RS'!D16 -> 45.7 | D13: =+D12+D12*((C13-C12)/C12-0.011) -> 41.457941 | E13: =+ROUND(D13/$D$37,3) -> 0.46 | G13: =+(C13-C12)/C12 -> 0.015555556 | H13: =+(D13-D12)/D12 -> 0.0045555556 | I13: =+H13-G13 -> -0.011 | K13: =+ROUND(C13/$C$62,3) -> 0.16 | L13: =+ROUND(D13/$D$62,3) -> 0.248
B14: 1957 | C14: ='CPI-U-RS'!D17 -> 47.2 | D14: =+D13+D13*((C14-C13)/C13-0.011) -> 42.362668 | E14: =+ROUND(D14/$D$37,3) -> 0.47 | G14: =+(C14-C13)/C13 -> 0.032822757 | H14: =+(D14-D13)/D13 -> 0.021822757 | I14: =+H14-G14 -> -0.011 | K14: =+ROUND(C14/$C$62,3) -> 0.165 | L14: =+ROUND(D14/$D$62,3) -> 0.253
B15: 1958 | C15: ='CPI-U-RS'!D18 -> 48.5 | D15: =+D14+D14*((C15-C14)/C14-0.011) -> 43.063447 | E15: =+ROUND(D15/$D$37,3) -> 0.478 | G15: =+(C15-C14)/C14 -> 0.027542373 | H15: =+(D15-D14)/D14 -> 0.016542373 | I15: =+H15-G15 -> -0.011 | K15: =+ROUND(C15/$C$62,3) -> 0.169 | L15: =+ROUND(D15/$D$62,3) -> 0.257
B16: 1959 | C16: ='CPI-U-RS'!D19 -> 48.9 | D16: =+D15+D15*((C16-C15)/C15-0.011) -> 42.944911 | E16: =+ROUND(D16/$D$37,3) -> 0.476 | G16: =+(C16-C15)/C15 -> 0.0082474227 | H16: =+(D16-D15)/D15 -> -0.0027525773 | I16: =+H16-G16 -> -0.011 | K16: =+ROUND(C16/$C$62,3) -> 0.171 | L16: =+ROUND(D16/$D$62,3) -> 0.257
... B33: 1976 | C33: ='CPI-U-RS'!D36 -> 91.9 | D33: =+D32+D32*((C33-C32)/C32-0.011) -> 67.332273 | E33: =+ROUND(D33/$D$37,3) -> 0.747 | G33: =+(C33-C32)/C32 -> 0.057537399 | H33: =+(D33-D32)/D32 -> 0.046537399 | I33: =+H33-G33 -> -0.011 | K33: =+ROUND(C33/$C$62,3) -> 0.321 | L33: =+ROUND(D33/$D$62,3) -> 0.403
A34: BEFORE 77 ADJ USING 1.1 | B34: 1977 | C34: ='CPI-U-RS'!D37 -> 97.7 | D34: =+D33+D33*((C34-C33)/C33-0.011) -> 70.841098 | E34: =+ROUND(D34/$D$37,3) -> 0.786 | G34: =+(C34-C33)/C33 -> 0.063112078 | H34: =+(D34-D33)/D33 -> 0.052112078 | I34: =+H34-G34 -> -0.011 | K34: =+ROUND(C34/$C$62,3) -> 0.341 | L34: =+ROUND(D34/$D$62,3) -> 0.424
B35: 1978 | C35: ='CPI-U-RS'!D38 -> 104.4 | D35: =+D34+D34*((C35-C34)/C34-0.008) -> 75.132458 | E35: =+ROUND(D35/$D$37,3) -> 0.833 | G35: =+(C35-C34)/C34 -> 0.068577277 | H35: =+(D35-D34)/D34 -> 0.060577277 | I35: =+H35-G35 -> -0.008 | K35: =+ROUND(C35/$C$62,3) -> 0.365 | L35: =+ROUND(D35/$D$62,3) -> 0.449
B36: 1979 | C36: ='CPI-U-RS'!D39 -> 114.3 | D36: =+D35+D35*((C36-C35)/C35-0.008) -> 81.656028 | E36: =+ROUND(D36/$D$37,3) -> 0.906 | G36: =+(C36-C35)/C35 -> 0.094827586 | H36: =+(D36-D35)/D35 -> 0.086827586 | I36: =+H36-G36 -> -0.008 | K36: =+ROUND(C36/$C$62,3) -> 0.399 | L36: =+ROUND(D36/$D$62,3) -> 0.488
B37: 1980 | C37: ='CPI-U-RS'!D40 -> 127.1 | D37: =+D36+D36*((C37-C36)/C36-0.008) -> 90.147112 | E37: =+ROUND(D37/$D$37,3) -> 1 | G37: =+(C37-C36)/C36 -> 0.111986 | H37: =+(D37-D36)/D36 -> 0.103986 | I37: =+H37-G37 -> -0.008 | K37: =+ROUND(C37/$C$62,3) -> 0.444 | L37: =+ROUND(D37/$D$62,3) -> 0.539
B38: 1981 | C38: ='CPI-U-RS'!D41 -> 139.1 | D38: =+D37+D37*((C38-C37)/C37-0.008) -> 97.937071 | E38: =+ROUND(D38/$D$37,3) -> 1.086 | G38: =+(C38-C37)/C37 -> 0.094413847 | H38: =+(D38-D37)/D37 -> 0.086413847 | I38: =+H38-G38 -> -0.008 | K38: =+ROUND(C38/$C$62,3) -> 0.486 | L38: =+ROUND(D38/$D$62,3) -> 0.586
B39: 1982 | C39: ='CPI-U-RS'!D42 -> 147.5 | D39: =+D38+D38*((C39-C38)/C38-0.008) -> 103.06782 | E39: =+ROUND(D39/$D$37,3) -> 1.143 | G39: =+(C39-C38)/C38 -> 0.06038821 | H39: =+(D39-D38)/D38 -> 0.05238821 | I39: =+H39-G39 -> -0.008 | K39: =+ROUND(C39/$C$62,3) -> 0.515 | L39: =+ROUND(D39/$D$62,3) -> 0.616
B40: 1983 | C40: ='CPI-U-RS'!D43 -> 153.8 | D40: =+D39+D39*((C40-C39)/C39-0.008) -> 106.6455 | E40: =+ROUND(D40/$D$37,3) -> 1.183 | G40: =+(C40-C39)/C39 -> 0.042711864 | H40: =+(D40-D39)/D39 -> 0.034711864 | I40: =+H40-G40 -> -0.008 | K40: =+ROUND(C40/$C$62,3) -> 0.537 | L40: =+ROUND(D40/$D$62,3) -> 0.638
B41: 1984 | C41: ='CPI-U-RS'!D44 -> 160.2 | D41: =+D40+D40*((C41-C40)/C40-0.008) -> 110.23012 | E41: =+ROUND(D41/$D$37,3) -> 1.223 | G41: =+(C41-C40)/C40 -> 0.041612484 | H41: =+(D41-D40)/D40 -> 0.033612484 | I41: =+H41-G41 -> -0.008 | K41: =+ROUND(C41/$C$62,3) -> 0.559 | L41: =+ROUND(D41/$D$62,3) -> 0.659
B42: 1985 | C42: ='CPI-U-RS'!D45 -> 165.6 | D42: =+D41+D41*((C42-C41)/C41-0.008) -> 113.0639 | E42: =+ROUND(D42/$D$37,3) -> 1.254 | G42: =+(C42-C41)/C41 -> 0.033707865 | H42: =+(D42-D41)/D41 -> 0.025707865 | I42: =+H42-G42 -> -0.008 | K42: =+ROUND(C42/$C$62,3) -> 0.578 | L42: =+ROUND(D42/$D$62,3) -> 0.676
B43: 1986 | C43: ='CPI-U-RS'!D46 -> 168.4 | D43: =+D42+D42*((C43-C42)/C42-0.008) -> 114.07109 | E43: =+ROUND(D43/$D$37,3) -> 1.265 | G43: =+(C43-C42)/C42 -> 0.016908213 | H43: =+(D43-D42)/D42 -> 0.0089082126 | I43: =+H43-G43 -> -0.008 | K43: =+ROUND(C43/$C$62,3) -> 0.588 | L43: =+ROUND(D43/$D$62,3) -> 0.682
B44: 1987 | C44: ='CPI-U-RS'!D47 -> 174.1 | D44: =+D43+D43*((C44-C43)/C43-0.008) -> 117.0196 | E44: =+ROUND(D44/$D$37,3) -> 1.298 | G44: =+(C44-C43)/C43 -> 0.033847981 | H44: =+(D44-D43)/D43 -> 0.025847981 | I44: =+H44-G44 -> -0.008 | K44: =+ROUND(C44/$C$62,3) -> 0.608 | L44: =+ROUND(D44/$D$62,3) -> 0.7
B45: 1988 | C45: ='CPI-U-RS'!D48 -> 180.5 | D45: =+D44+D44*((C45-C44)/C44-0.008) -> 120.38514 | E45: =+ROUND(D45/$D$37,3) -> 1.335 | G45: =+(C45-C44)/C44 -> 0.036760482 | H45: =+(D45-D44)/D44 -> 0.028760482 | I45: =+H45-G45 -> -0.008 | K45: =+ROUND(C45/$C$62,3) -> 0.63 | L45: =+ROUND(D45/$D$62,3) -> 0.72
B46: 1989 | C46: ='CPI-U-RS'!D49 -> 188.3 | D46: =+D45+D45*((C46-C45)/C45-0.008) -> 124.6243 | E46: =+ROUND(D46/$D$37,3) -> 1.382 | G46: =+(C46-C45)/C45 -> 0.043213296 | H46: =+(D46-D45)/D45 -> 0.035213296 | I46: =+H46-G46 -> -0.008 | K46: =+ROUND(C46/$C$62,3) -> 0.657 | L46: =+ROUND(D46/$D$62,3) -> 0.745
... B62: 2005 | C62: ='CPI-U-RS'!D65 -> 286.4 | D62: =+D61+D61*((C62-C61)/C61-0.008) -> 167.24758 | E62: =+ROUND(D62/$D$37,3) -> 1.855 | G62: =+(C62-C61)/C61 -> 0.033935018 | H62: =+(D62-D61)/D61 -> 0.025935018 | I62: =+H62-G62 -> -0.008 | K62: =+ROUND(C62/$C$62,3) -> 1 | L62: =+ROUND(D62/$D$62,3) -> 1
B63: =+B62+1 -> 2006 | C63: ='CPI-U-RS'!D66 -> 295.7 | D63: =+D62+D62*((C63-C62)/C62-0.008) -> 171.34048 | E63: =+ROUND(D63/$D$37,3) -> 1.901 | G63: =+(C63-C62)/C62 -> 0.032472067 | H63: =+(D63-D62)/D62 -> 0.024472067 | I63: =+H63-G63 -> -0.008 | K63: =+ROUND(C63/$C$62,3) -> 1.032 | L63: =+ROUND(D63/$D$62,3) -> 1.024
B64: =+B63+1 -> 2007 | C64: ='CPI-U-RS'!D67 -> 304.1 | D64: =+D63+D63*((C64-C63)/C63-0.008) -> 174.83705 | E64: =+ROUND(D64/$D$37,3) -> 1.939 | G64: =+(C64-C63)/C63 -> 0.028407169 | H64: =+(D64-D63)/D63 -> 0.020407169 | I64: =+H64-G64 -> -0.008 | K64: =+ROUND(C64/$C$62,3) -> 1.062 | L64: =+ROUND(D64/$D$62,3) -> 1.045
B65: =+B64+1 -> 2008 | C65: ='CPI-U-RS'!D68 -> 315.8 | D65: =+D64+D64*((C65-C64)/C64-0.008) -> 180.16507 | E65: =+ROUND(D65/$D$37,3) -> 1.999 | G65: =+(C65-C64)/C64 -> 0.038474186 | H65: =+(D65-D64)/D64 -> 0.030474186 | I65: =+H65-G65 -> -0.008 | K65: =+ROUND(C65/$C$62,3) -> 1.103 | L65: =+ROUND(D65/$D$62,3) -> 1.077
B66: =+B65+1 -> 2009 | C66: ='CPI-U-RS'!D69 -> 314.7 | D66: =+D65+D65*((C66-C65)/C65-0.008) -> 178.09619 | E66: =+ROUND(D66/$D$37,3) -> 1.976 | G66: =+(C66-C65)/C65 -> -0.0034832172 | H66: =+(D66-D65)/D65 -> -0.011483217 | I66: =+H66-G66 -> -0.008 | K66: =+ROUND(C66/$C$62,3) -> 1.099 | L66: =+ROUND(D66/$D$62,3) -> 1.065
B67: =+B66+1 -> 2010 | C67: ='CPI-U-RS'!D70 -> 319.8 | D67: =+D66+D66*((C67-C66)/C66-0.008) -> 179.55764 | E67: =+ROUND(D67/$D$37,3) -> 1.992 | G67: =+(C67-C66)/C66 -> 0.01620591 | H67: =+(D67-D66)/D66 -> 0.0082059104 | I67: =+H67-G67 -> -0.008 | K67: =+ROUND(C67/$C$62,3) -> 1.117 | L67: =+ROUND(D67/$D$62,3) -> 1.074
B68: =+B67+1 -> 2011 | C68: ='CPI-U-RS'!D71 -> 330 | D68: =+D67+D67*((C68-C67)/C67-0.008) -> 183.84815 | E68: =+ROUND(D68/$D$37,3) -> 2.039 | G68: =+(C68-C67)/C67 -> 0.031894934 | H68: =+(D68-D67)/D67 -> 0.023894934 | I68: =+H68-G68 -> -0.008 | K68: =+ROUND(C68/$C$62,3) -> 1.152 | L68: =+ROUND(D68/$D$62,3) -> 1.099
B69: =+B68+1 -> 2012 | C69: ='CPI-U-RS'!D72 -> 336.9 | D69: =+D68+D68*((C69-C68)/C68-0.008) -> 186.22147 | E69: =+ROUND(D69/$D$37,3) -> 2.066 | G69: =+(C69-C68)/C68 -> 0.020909091 | H69: =+(D69-D68)/D68 -> 0.012909091 | I69: =+H69-G69 -> -0.008 | K69: =+ROUND(C69/$C$62,3) -> 1.176 | L69: =+ROUND(D69/$D$62,3) -> 1.113
B70: =+B69+1 -> 2013 | C70: ='CPI-U-RS'!D73 -> 342 | D70: =+D69+D69*((C70-C69)/C69-0.008) -> 187.55072 | E70: =+ROUND(D70/$D$37,3) -> 2.08 | G70: =+(C70-C69)/C69 -> 0.015138023 | H70: =+(D70-D69)/D69 -> 0.0071380232 | I70: =+H70-G70 -> -0.008 | K70: =+ROUND(C70/$C$62,3) -> 1.194 | L70: =+ROUND(D70/$D$62,3) -> 1.121
B71: =+B70+1 -> 2014 | C71: ='CPI-U-RS'!D74 -> 347.7 | D71: =+D70+D70*((C71-C70)/C70-0.008) -> 189.17616 | E71: =+ROUND(D71/$D$37,3) -> 2.099 | G71: =+(C71-C70)/C70 -> 0.016666667 | H71: =+(D71-D70)/D70 -> 0.0086666667 | I71: =+H71-G71 -> -0.008 | K71: =+ROUND(C71/$C$62,3) -> 1.214 | L71: =+ROUND(D71/$D$62,3) -> 1.131
B72: =+B71+1 -> 2015 | C72: ='CPI-U-RS'!D75 -> 348.3 | D72: =+D71+D71*((C72-C71)/C71-0.008) -> 187.9892 | E72: =+ROUND(D72/$D$37,3) -> 2.085 | G72: =+(C72-C71)/C71 -> 0.0017256255 | H72: =+(D72-D71)/D71 -> -0.0062743745 | I72: =+H72-G72 -> -0.008 | K72: =+ROUND(C72/$C$62,3) -> 1.216 | L72: =+ROUND(D72/$D$62,3) -> 1.124
B73: =+B72+1 -> 2016 | C73: ='CPI-U-RS'!D76 -> 352.8 | D73: =+D72+D72*((C73-C72)/C72-0.008) -> 188.91408 | E73: =+ROUND(D73/$D$37,3) -> 2.096 | G73: =+(C73-C72)/C72 -> 0.012919897 | H73: =+(D73-D72)/D72 -> 0.0049198966 | I73: =+H73-G73 -> -0.008 | K73: =+ROUND(C73/$C$62,3) -> 1.232 | L73: =+ROUND(D73/$D$62,3) -> 1.13
...

Sheet cpi-u-rs-adj-03
C3: cpi-u-rs | D3: cpi-u-rs-adj .5% | E3: base=1980 | G3: check
B4: 1947 | C4: ='CPI-U-RS'!D7 -> 37.5 | D4: =+C4 -> 37.5 | E4: =+ROUND(D4/$D$37,3) -> 0.413 | K4: =+ROUND(C4/$C$62,3) -> 0.131 | L4: =+ROUND(D4/$D$62,3) -> 0.207
B5: 1948 | C5: ='CPI-U-RS'!D8 -> 40.5 | D5: =+D4+D4*((C5-C4)/C4-0.011) -> 40.0875 | E5: =+ROUND(D5/$D$37,3) -> 0.441 | G5: =+(C5-C4)/C4 -> 0.08 | H5: =+(D5-D4)/D4 -> 0.069 | I5: =+H5-G5 -> -0.011 | K5: =+ROUND(C5/$C$62,3) -> 0.141 | L5: =+ROUND(D5/$D$62,3) -> 0.221
B6: 1949 | C6: ='CPI-U-RS'!D9 -> 40 | D6: =+D5+D5*((C6-C5)/C5-0.011) -> 39.15163 | E6: =+ROUND(D6/$D$37,3) -> 0.431 | G6: =+(C6-C5)/C5 -> -0.012345679 | H6: =+(D6-D5)/D5 -> -0.023345679 | I6: =+H6-G6 -> -0.011 | K6: =+ROUND(C6/$C$62,3) -> 0.14 | L6: =+ROUND(D6/$D$62,3) -> 0.216
B7: 1950 | C7: ='CPI-U-RS'!D10 -> 40.5 | D7: =+D6+D6*((C7-C6)/C6-0.011) -> 39.210358 | E7: =+ROUND(D7/$D$37,3) -> 0.431 | G7: =+(C7-C6)/C6 -> 0.0125 | H7: =+(D7-D6)/D6 -> 0.0015 | I7: =+H7-G7 -> -0.011 | K7: =+ROUND(C7/$C$62,3) -> 0.141 | L7: =+ROUND(D7/$D$62,3) -> 0.216
B8: 1951 | C8: ='CPI-U-RS'!D11 -> 43.7 | D8: =+D7+D7*((C8-C7)/C7-0.011) -> 41.877146 | E8: =+ROUND(D8/$D$37,3) -> 0.461 | G8: =+(C8-C7)/C7 -> 0.079012346 | H8: =+(D8-D7)/D7 -> 0.068012346 | I8: =+H8-G8 -> -0.011 | K8: =+ROUND(C8/$C$62,3) -> 0.153 | L8: =+ROUND(D8/$D$62,3) -> 0.231
B9: 1952 | C9: ='CPI-U-RS'!D12 -> 44.5 | D9: =+D8+D8*((C9-C8)/C8-0.011) -> 42.183127 | E9: =+ROUND(D9/$D$37,3) -> 0.464 | G9: =+(C9-C8)/C8 -> 0.018306636 | H9: =+(D9-D8)/D8 -> 0.0073066362 | I9: =+H9-G9 -> -0.011 | K9: =+ROUND(C9/$C$62,3) -> 0.155 | L9: =+ROUND(D9/$D$62,3) -> 0.233
B10: 1953 | C10: ='CPI-U-RS'!D13 -> 44.8 | D10: =+D9+D9*((C10-C9)/C9-0.011) -> 42.003493 | E10: =+ROUND(D10/$D$37,3) -> 0.462 | G10: =+(C10-C9)/C9 -> 0.006741573 | H10: =+(D10-D9)/D9 -> -0.004258427 | I10: =+H10-G10 -> -0.011 | K10: =+ROUND(C10/$C$62,3) -> 0.156 | L10: =+ROUND(D10/$D$62,3) -> 0.232
B11: 1954 | C11: ='CPI-U-RS'!D14 -> 45.2 | D11: =+D10+D10*((C11-C10)/C10-0.011) -> 41.916486 | E11: =+ROUND(D11/$D$37,3) -> 0.461 | G11: =+(C11-C10)/C10 -> 0.0089285714 | H11: =+(D11-D10)/D10 -> -0.0020714286 | I11: =+H11-G11 -> -0.011 | K11: =+ROUND(C11/$C$62,3) -> 0.158 | L11: =+ROUND(D11/$D$62,3) -> 0.231
B12: 1955 | C12: ='CPI-U-RS'!D15 -> 45 | D12: =+D11+D11*((C12-C11)/C11-0.011) -> 41.269933 | E12: =+ROUND(D12/$D$37,3) -> 0.454 | G12: =+(C12-C11)/C11 -> -0.0044247788 | H12: =+(D12-D11)/D11 -> -0.015424779 | I12: =+H12-G12 -> -0.011 | K12: =+ROUND(C12/$C$62,3) -> 0.157 | L12: =+ROUND(D12/$D$62,3) -> 0.227
B13: 1956 | C13: ='CPI-U-RS'!D16 -> 45.7 | D13: =+D12+D12*((C13-C12)/C12-0.011) -> 41.457941 | E13: =+ROUND(D13/$D$37,3) -> 0.456 | G13: =+(C13-C12)/C12 -> 0.015555556 | H13: =+(D13-D12)/D12 -> 0.0045555556 | I13: =+H13-G13 -> -0.011 | K13: =+ROUND(C13/$C$62,3) -> 0.16 | L13: =+ROUND(D13/$D$62,3) -> 0.229
B14: 1957 | C14: ='CPI-U-RS'!D17 -> 47.2 | D14: =+D13+D13*((C14-C13)/C13-0.011) -> 42.362668 | E14: =+ROUND(D14/$D$37,3) -> 0.466 | G14: =+(C14-C13)/C13 -> 0.032822757 | H14: =+(D14-D13)/D13 -> 0.021822757 | I14: =+H14-G14 -> -0.011 | K14: =+ROUND(C14/$C$62,3) -> 0.165 | L14: =+ROUND(D14/$D$62,3) -> 0.233
B15: 1958 | C15: ='CPI-U-RS'!D18 -> 48.5 | D15: =+D14+D14*((C15-C14)/C14-0.011) -> 43.063447 | E15: =+ROUND(D15/$D$37,3) -> 0.474 | G15: =+(C15-C14)/C14 -> 0.027542373 | H15: =+(D15-D14)/D14 -> 0.016542373 | I15: =+H15-G15 -> -0.011 | K15: =+ROUND(C15/$C$62,3) -> 0.169 | L15: =+ROUND(D15/$D$62,3) -> 0.237
B16: 1959 | C16: ='CPI-U-RS'!D19 -> 48.9 | D16: =+D15+D15*((C16-C15)/C15-0.011) -> 42.944911 | E16: =+ROUND(D16/$D$37,3) -> 0.472 | G16: =+(C16-C15)/C15 -> 0.0082474227 | H16: =+(D16-D15)/D15 -> -0.0027525773 | I16: =+H16-G16 -> -0.011 | K16: =+ROUND(C16/$C$62,3) -> 0.171 | L16: =+ROUND(D16/$D$62,3) -> 0.237
... B33: 1976 | C33: ='CPI-U-RS'!D36 -> 91.9 | D33: =+D32+D32*((C33-C32)/C32-0.011) -> 67.332273 | E33: =+ROUND(D33/$D$37,3) -> 0.741 | G33: =+(C33-C32)/C32 -> 0.057537399 | H33: =+(D33-D32)/D32 -> 0.046537399 | I33: =+H33-G33 -> -0.011 | K33: =+ROUND(C33/$C$62,3) -> 0.321 | L33: =+ROUND(D33/$D$62,3) -> 0.371
A34: BEFORE 77 ADJ USING 1.1 | B34: 1977 | C34: ='CPI-U-RS'!D37 -> 97.7 | D34: =+D33+D33*((C34-C33)/C33-0.011) -> 70.841098 | E34: =+ROUND(D34/$D$37,3) -> 0.779 | G34: =+(C34-C33)/C33 -> 0.063112078 | H34: =+(D34-D33)/D33 -> 0.052112078 | I34: =+H34-G34 -> -0.011 | K34: =+ROUND(C34/$C$62,3) -> 0.341 | L34: =+ROUND(D34/$D$62,3) -> 0.39
B35: 1978 | C35: ='CPI-U-RS'!D38 -> 104.4 | D35: =+D34+D34*((C35-C34)/C34-0.005) -> 75.344982 | E35: =+ROUND(D35/$D$37,3) -> 0.829 | G35: =+(C35-C34)/C34 -> 0.068577277 | H35: =+(D35-D34)/D34 -> 0.063577277 | I35: =+H35-G35 -> -0.005 | K35: =+ROUND(C35/$C$62,3) -> 0.365 | L35: =+ROUND(D35/$D$62,3) -> 0.415
B36: 1979 | C36: ='CPI-U-RS'!D39 -> 114.3 | D36: =+D35+D35*((C36-C35)/C35-0.005) -> 82.11304 | E36: =+ROUND(D36/$D$37,3) -> 0.903 | G36: =+(C36-C35)/C35 -> 0.094827586 | H36: =+(D36-D35)/D35 -> 0.089827586 | I36: =+H36-G36 -> -0.005 | K36: =+ROUND(C36/$C$62,3) -> 0.399 | L36: =+ROUND(D36/$D$62,3) -> 0.453
B37: 1980 | C37: ='CPI-U-RS'!D40 -> 127.1 | D37: =+D36+D36*((C37-C36)/C36-0.005) -> 90.897985 | E37: =+ROUND(D37/$D$37,3) -> 1 | G37: =+(C37-C36)/C36 -> 0.111986 | H37: =+(D37-D36)/D36 -> 0.106986 | I37: =+H37-G37 -> -0.005 | K37: =+ROUND(C37/$C$62,3) -> 0.444 | L37: =+ROUND(D37/$D$62,3) -> 0.501
B38: 1981 | C38: ='CPI-U-RS'!D41 -> 139.1 | D38: =+D37+D37*((C38-C37)/C37-0.005) -> 99.025524 | E38: =+ROUND(D38/$D$37,3) -> 1.089 | G38: =+(C38-C37)/C37 -> 0.094413847 | H38: =+(D38-D37)/D37 -> 0.089413847 | I38: =+H38-G38 -> -0.005 | K38: =+ROUND(C38/$C$62,3) -> 0.486 | L38: =+ROUND(D38/$D$62,3) -> 0.546
B39: 1982 | C39: ='CPI-U-RS'!D42 -> 147.5 | D39: =+D38+D38*((C39-C38)/C38-0.005) -> 104.51037 | E39: =+ROUND(D39/$D$37,3) -> 1.15 | G39: =+(C39-C38)/C38 -> 0.06038821 | H39: =+(D39-D38)/D38 -> 0.05538821 | I39: =+H39-G39 -> -0.005 | K39: =+ROUND(C39/$C$62,3) -> 0.515 | L39: =+ROUND(D39/$D$62,3) -> 0.576
B40: 1983 | C40: ='CPI-U-RS'!D43 -> 153.8 | D40: =+D39+D39*((C40-C39)/C39-0.005) -> 108.45165 | E40: =+ROUND(D40/$D$37,3) -> 1.193 | G40: =+(C40-C39)/C39 -> 0.042711864 | H40: =+(D40-D39)/D39 -> 0.037711864 | I40: =+H40-G40 -> -0.005 | K40: =+ROUND(C40/$C$62,3) -> 0.537 | L40: =+ROUND(D40/$D$62,3) -> 0.598
B41: 1984 | C41: ='CPI-U-RS'!D44 -> 160.2 | D41: =+D40+D40*((C41-C40)/C40-0.005) -> 112.42234 | E41: =+ROUND(D41/$D$37,3) -> 1.237 | G41: =+(C41-C40)/C40 -> 0.041612484 | H41: =+(D41-D40)/D40 -> 0.036612484 | I41: =+H41-G41 -> -0.005 | K41: =+ROUND(C41/$C$62,3) -> 0.559 | L41: =+ROUND(D41/$D$62,3) -> 0.62
B42: 1985 | C42: ='CPI-U-RS'!D45 -> 165.6 | D42: =+D41+D41*((C42-C41)/C41-0.005) -> 115.64974 | E42: =+ROUND(D42/$D$37,3) -> 1.272 | G42: =+(C42-C41)/C41 -> 0.033707865 | H42: =+(D42-D41)/D41 -> 0.028707865 | I42: =+H42-G42 -> -0.005 | K42: =+ROUND(C42/$C$62,3) -> 0.578 | L42: =+ROUND(D42/$D$62,3) -> 0.637
B43: 1986 | C43: ='CPI-U-RS'!D46 -> 168.4 | D43: =+D42+D42*((C43-C42)/C42-0.005) -> 117.02692 | E43: =+ROUND(D43/$D$37,3) -> 1.287 | G43: =+(C43-C42)/C42 -> 0.016908213 | H43: =+(D43-D42)/D42 -> 0.011908213 | I43: =+H43-G43 -> -0.005 | K43: =+ROUND(C43/$C$62,3) -> 0.588 | L43: =+ROUND(D43/$D$62,3) -> 0.645
B44: 1987 | C44: ='CPI-U-RS'!D47 -> 174.1 | D44: =+D43+D43*((C44-C43)/C43-0.005) -> 120.40291 | E44: =+ROUND(D44/$D$37,3) -> 1.325 | G44: =+(C44-C43)/C43 -> 0.033847981 | H44: =+(D44-D43)/D43 -> 0.028847981 | I44: =+H44-G44 -> -0.005 | K44: =+ROUND(C44/$C$62,3) -> 0.608 | L44: =+ROUND(D44/$D$62,3) -> 0.664
B45: 1988 | C45: ='CPI-U-RS'!D48 -> 180.5 | D45: =+D44+D44*((C45-C44)/C44-0.005) -> 124.22697 | E45: =+ROUND(D45/$D$37,3) -> 1.367 | G45: =+(C45-C44)/C44 -> 0.036760482 | H45: =+(D45-D44)/D44 -> 0.031760482 | I45: =+H45-G45 -> -0.005 | K45: =+ROUND(C45/$C$62,3) -> 0.63 | L45: =+ROUND(D45/$D$62,3) -> 0.685
B46: 1989 | C46: ='CPI-U-RS'!D49 -> 188.3 | D46: =+D45+D45*((C46-C45)/C45-0.005) -> 128.97409 | E46: =+ROUND(D46/$D$37,3) -> 1.419 | G46: =+(C46-C45)/C45 -> 0.043213296 | H46: =+(D46-D45)/D45 -> 0.038213296 | I46: =+H46-G46 -> -0.005 | K46: =+ROUND(C46/$C$62,3) -> 0.657 | L46: =+ROUND(D46/$D$62,3) -> 0.711
... B62: 2005 | C62: ='CPI-U-RS'!D65 -> 286.4 | D62: =+D61+D61*((C62-C61)/C61-0.005) -> 181.42476 | E62: =+ROUND(D62/$D$37,3) -> 1.996 | G62: =+(C62-C61)/C61 -> 0.033935018 | H62: =+(D62-D61)/D61 -> 0.028935018 | I62: =+H62-G62 -> -0.005 | K62: =+ROUND(C62/$C$62,3) -> 1 | L62: =+ROUND(D62/$D$62,3) -> 1
B63: =+B62+1 -> 2006 | C63: ='CPI-U-RS'!D66 -> 295.7 | D63: =+D62+D62*((C63-C62)/C62-0.005) -> 186.40888 | E63: =+ROUND(D63/$D$37,3) -> 2.051 | G63: =+(C63-C62)/C62 -> 0.032472067 | H63: =+(D63-D62)/D62 -> 0.027472067 | I63: =+H63-G63 -> -0.005 | K63: =+ROUND(C63/$C$62,3) -> 1.032 | L63: =+ROUND(D63/$D$62,3) -> 1.027
B64: =+B63+1 -> 2007 | C64: ='CPI-U-RS'!D67 -> 304.1 | D64: =+D63+D63*((C64-C63)/C63-0.005) -> 190.77218 | E64: =+ROUND(D64/$D$37,3) -> 2.099 | G64: =+(C64-C63)/C63 -> 0.028407169 | H64: =+(D64-D63)/D63 -> 0.023407169 | I64: =+H64-G64 -> -0.005 | K64: =+ROUND(C64/$C$62,3) -> 1.062 | L64: =+ROUND(D64/$D$62,3) -> 1.052
B65: =+B64+1 -> 2008 | C65: ='CPI-U-RS'!D68 -> 315.8 | D65: =+D64+D64*((C65-C64)/C64-0.005) -> 197.15812 | E65: =+ROUND(D65/$D$37,3) -> 2.169 | G65: =+(C65-C64)/C64 -> 0.038474186 | H65: =+(D65-D64)/D64 -> 0.033474186 | I65: =+H65-G65 -> -0.005 | K65: =+ROUND(C65/$C$62,3) -> 1.103 | L65: =+ROUND(D65/$D$62,3) -> 1.087
B66: =+B65+1 -> 2009 | C66: ='CPI-U-RS'!D69 -> 314.7 | D66: =+D65+D65*((C66-C65)/C65-0.005) -> 195.48559 | E66: =+ROUND(D66/$D$37,3) -> 2.151 | G66: =+(C66-C65)/C65 -> -0.0034832172 | H66: =+(D66-D65)/D65 -> -0.0084832172 | I66: =+H66-G66 -> -0.005 | K66: =+ROUND(C66/$C$62,3) -> 1.099 | L66: =+ROUND(D66/$D$62,3) -> 1.078
B67: =+B66+1 -> 2010 | C67: ='CPI-U-RS'!D70 -> 319.8 | D67: =+D66+D66*((C67-C66)/C66-0.005) -> 197.67618 | E67: =+ROUND(D67/$D$37,3) -> 2.175 | G67: =+(C67-C66)/C66 -> 0.01620591 | H67: =+(D67-D66)/D66 -> 0.01120591 | I67: =+H67-G67 -> -0.005 | K67: =+ROUND(C67/$C$62,3) -> 1.117 | L67: =+ROUND(D67/$D$62,3) -> 1.09
B68: =+B67+1 -> 2011 | C68: ='CPI-U-RS'!D71 -> 330 | D68: =+D67+D67*((C68-C67)/C67-0.005) -> 202.99267 | E68: =+ROUND(D68/$D$37,3) -> 2.233 | G68: =+(C68-C67)/C67 -> 0.031894934 | H68: =+(D68-D67)/D67 -> 0.026894934 | I68: =+H68-G68 -> -0.005 | K68: =+ROUND(C68/$C$62,3) -> 1.152 | L68: =+ROUND(D68/$D$62,3) -> 1.119
B69: =+B68+1 -> 2012 | C69: ='CPI-U-RS'!D72 -> 336.9 | D69: =+D68+D68*((C69-C68)/C68-0.005) -> 206.2221 | E69: =+ROUND(D69/$D$37,3) -> 2.269 | G69: =+(C69-C68)/C68 -> 0.020909091 | H69: =+(D69-D68)/D68 -> 0.015909091 | I69: =+H69-G69 -> -0.005 | K69: =+ROUND(C69/$C$62,3) -> 1.176 | L69: =+ROUND(D69/$D$62,3) -> 1.137
B70: =+B69+1 -> 2013 | C70: ='CPI-U-RS'!D73 -> 342 | D70: =+D69+D69*((C70-C69)/C69-0.005) -> 208.31278 | E70: =+ROUND(D70/$D$37,3) -> 2.292 | G70: =+(C70-C69)/C69 -> 0.015138023 | H70: =+(D70-D69)/D69 -> 0.010138023 | I70: =+H70-G70 -> -0.005 | K70: =+ROUND(C70/$C$62,3) -> 1.194 | L70: =+ROUND(D70/$D$62,3) -> 1.148
B71: =+B70+1 -> 2014 | C71: ='CPI-U-RS'!D74 -> 347.7 | D71: =+D70+D70*((C71-C70)/C70-0.005) -> 210.7431 | E71: =+ROUND(D71/$D$37,3) -> 2.318 | G71: =+(C71-C70)/C70 -> 0.016666667 | H71: =+(D71-D70)/D70 -> 0.011666667 | I71: =+H71-G71 -> -0.005 | K71: =+ROUND(C71/$C$62,3) -> 1.214 | L71: =+ROUND(D71/$D$62,3) -> 1.162
B72: =+B71+1 -> 2015 | C72: ='CPI-U-RS'!D75 -> 348.3 | D72: =+D71+D71*((C72-C71)/C71-0.005) -> 210.05305 | E72: =+ROUND(D72/$D$37,3) -> 2.311 | G72: =+(C72-C71)/C71 -> 0.0017256255 | H72: =+(D72-D71)/D71 -> -0.0032743745 | I72: =+H72-G72 -> -0.005 | K72: =+ROUND(C72/$C$62,3) -> 1.216 | L72: =+ROUND(D72/$D$62,3) -> 1.158
